Workbook

Sheet Dashboard
B1: DASHBOARD — HELSE 2026
B2: Nøkkeltall samlet fra Dagslogg, Treningslogg, Vekt og Oversikt. Alt beregnes automatisk — ingen inntasting på dette arket.
B4: STATUS — HELE PERIODEN (UKE 31–51)
B6: VEKT NÅ | D6: FAKTISK TAP HITTIL | F6: LIVVIDDE NÅ | H6: UNDERSKUDD HITTIL | J6: MÅLOPPNÅELSE | L6: FREMSKREVET SLUTTVEKT
B7: =IFERROR(LOOKUP(2,1/(Dagslogg[Vekt]<>""),Dagslogg[Vekt]),"") -> 77.5 | D7: =IF(Vekt!$U$7="","",Vekt!$U$7) -> -0.05 | F7: =IFERROR(LOOKUP(2,1/(Dagslogg[Vidde]<>""),Dagslogg[Vidde]),"") -> 88.5 | H7: =Vekt!$U$4 -> 2100 | J7: =IF(Vekt!$U$5="","",Vekt!$U$5) -> 1.05 | L7: =IF(Vekt!$U$10="","",Vekt!$E$5-Vekt!$U$10) -> 60.79
B8: ="start: "&Vekt!$E$5&" kg" -> start: 77.45 kg | D8: =IF(Vekt!$U$6="","","estimert fra kcal: "&ROUND(Vekt!$U$6,2)&" kg") -> estimert fra kcal: 0.28 kg | F8: =IF(Vekt!$U$8="","","reduksjon: "&ROUND(Vekt!$U$8,2)&" cm (start "&Vekt!$E$6&")") -> reduksjon: 1.25 cm (start 90) | H8: ="≈ "&ROUND(Vekt!$U$4/Vekt!$E$7*1000,0)&" gram fett" -> ≈ 280 gram fett | J8: underskudd vs. ukemål hittil | L8: ="mål uke 51: "&ROUND(Vekt!$E$5-Vekt!$U$9,1)&" kg" -> mål uke 51: 61.6 kg
B10: ="DENNE UKEN — UKE "&_xlfn.ISOWEEKNUM(TODAY())&" · "&TEXT((TODAY()-WEEKDAY(TODAY(),3)),"dd.mm")&"–"&TEXT((TODAY()-WEEKDAY(TODAY(),3))+6,"dd.mm") -> DENNE UKEN — UKE 31 · 27.07–02.08
B12: ØKTER DENNE UKEN | F12: KALORIUNDERSKUDD DENNE UKEN | J12: DAGER LOGGET DENNE UKEN
B13: =COUNTIFS(Treningslogg[Dato],">="&(TODAY()-WEEKDAY(TODAY(),3)),Treningslogg[Dato],"<="&(TODAY()-WEEKDAY(TODAY(),3))+6,Treningslogg[Type],"<>") -> 11 | F13: =SUMIFS(Dagslogg[Minus],Dagslogg[Dato],">="&(TODAY()-WEEKDAY(TODAY(),3)),Dagslogg[Dato],"<="&(TODAY()-WEEKDAY(TODAY(),3))+6) -> 2100 | J13: =COUNTIFS(Dagslogg[Dato],">="&(TODAY()-WEEKDAY(TODAY(),3)),Dagslogg[Dato],"<="&(TODAY()-WEEKDAY(TODAY(),3))+6,Dagslogg[Minus],"<>") -> 2
B14: program: 3 × styrke + løping (jf. Guide §12) | F14: =IFERROR("mål: "&(7*INDEX(Vekt!$T$14:$T$34,_xlfn.ISOWEEKNUM(TODAY())-30))&" kcal for hele uken","") -> mål: 7000 kcal for hele uken | J14: dager med kalorier ført i Dagslogg
B16: TRENING PER TYPE — HELE HØSTEN
B18: TYPE | D18: ØKTER | E18: TIMER | F18: KM
B19: Styrketrening | D19: =COUNTIFS(Treningslogg[Type],$B19) -> 3 | E19: =SUMIFS(Treningslogg[Varighet (min)],Treningslogg[Type],$B19)/60 -> 0 | F19: =SUMIFS(Treningslogg[Distanse (km)],Treningslogg[Type],$B19) -> 0 | G19: =IF($D19=0,"",REPT("█",MAX(1,ROUND(14*$D19/MAX($D$19:$D$25),0)))) -> ██████████████
B20: Løping | D20: =COUNTIFS(Treningslogg[Type],$B20) -> 2 | E20: =SUMIFS(Treningslogg[Varighet (min)],Treningslogg[Type],$B20)/60 -> 0 | F20: =SUMIFS(Treningslogg[Distanse (km)],Treningslogg[Type],$B20) -> 0 | G20: =IF($D20=0,"",REPT("█",MAX(1,ROUND(14*$D20/MAX($D$19:$D$25),0)))) -> █████████
B21: Sykling | D21: =COUNTIFS(Treningslogg[Type],$B21) -> 2 | E21: =SUMIFS(Treningslogg[Varighet (min)],Treningslogg[Type],$B21)/60 -> 0 | F21: =SUMIFS(Treningslogg[Distanse (km)],Treningslogg[Type],$B21) -> 0 | G21: =IF($D21=0,"",REPT("█",MAX(1,ROUND(14*$D21/MAX($D$19:$D$25),0)))) -> █████████
B22: Svømming | D22: =COUNTIFS(Treningslogg[Type],$B22) -> 1 | E22: =SUMIFS(Treningslogg[Varighet (min)],Treningslogg[Type],$B22)/60 -> 0 | F22: =SUMIFS(Treningslogg[Distanse (km)],Treningslogg[Type],$B22) -> 0 | G22: =IF($D22=0,"",REPT("█",MAX(1,ROUND(14*$D22/MAX($D$19:$D$25),0)))) -> █████
B23: Karate | D23: =COUNTIFS(Treningslogg[Type],$B23) -> 1 | E23: =SUMIFS(Treningslogg[Varighet (min)],Treningslogg[Type],$B23)/60 -> 0 | F23: =SUMIFS(Treningslogg[Distanse (km)],Treningslogg[Type],$B23) -> 0 | G23: =IF($D23=0,"",REPT("█",MAX(1,ROUND(14*$D23/MAX($D$19:$D$25),0)))) -> █████
B24: Klatring | D24: =COUNTIFS(Treningslogg[Type],$B24) -> 1 | E24: =SUMIFS(Treningslogg[Varighet (min)],Treningslogg[Type],$B24)/60 -> 0 | F24: =SUMIFS(Treningslogg[Distanse (km)],Treningslogg[Type],$B24) -> 0 | G24: =IF($D24=0,"",REPT("█",MAX(1,ROUND(14*$D24/MAX($D$19:$D$25),0)))) -> █████
B25: Annet | D25: =COUNTIFS(Treningslogg[Type],$B25) -> 1 | E25: =SUMIFS(Treningslogg[Varighet (min)],Treningslogg[Type],$B25)/60 -> 0 | F25: =SUMIFS(Treningslogg[Distanse (km)],Treningslogg[Type],$B25) -> 0 | G25: =IF($D25=0,"",REPT("█",MAX(1,ROUND(14*$D25/MAX($D$19:$D$25),0)))) -> █████
B26: TOTALT | D26: =SUM(D19:D25) -> 11 | E26: =SUM(E19:E25) -> 0 | F26: =SUM(F19:F25) -> 0
B28: KALORIUNDERSKUDD UKE FOR UKE — MOT UKEMÅL
B30: UKE | C30: UNDERSKUDD | D30: UKEMÅL | E30: OPPNÅDD
B31: =Vekt!C14 -> 31 | C31: =IF(Vekt!R14="","",Vekt!R14) -> 2100 | D31: =IF(Vekt!S14="","",Vekt!S14) -> 2000 | E31: =IF(OR($C31="",$D31="",$D31=0),"",$C31/$D31) -> 1.05 | F31: =IF($E31="","",REPT("█",MIN(10,ROUND($E31*10,0)))&REPT("░",MAX(0,10-ROUND($E31*10,0)))&IF($E31>1.049," +","")) -> ██████████ +
B32: =Vekt!C15 -> 32 | C32: =IF(Vekt!R15="","",Vekt!R15) | D32: =IF(Vekt!S15="","",Vekt!S15) | E32: =IF(OR($C32="",$D32="",$D32=0),"",$C32/$D32) | F32: =IF($E32="","",REPT("█",MIN(10,ROUND($E32*10,0)))&REPT("░",MAX(0,10-ROUND($E32*10,0)))&IF($E32>1.049," +",""))
B33: =Vekt!C16 -> 33 | C33: =IF(Vekt!R16="","",Vekt!R16) | D33: =IF(Vekt!S16="","",Vekt!S16) | E33: =IF(OR($C33="",$D33="",$D33=0),"",$C33/$D33) | F33: =IF($E33="","",REPT("█",MIN(10,ROUND($E33*10,0)))&REPT("░",MAX(0,10-ROUND($E33*10,0)))&IF($E33>1.049," +",""))
B34: =Vekt!C17 -> 34 | C34: =IF(Vekt!R17="","",Vekt!R17) | D34: =IF(Vekt!S17="","",Vekt!S17) | E34: =IF(OR($C34="",$D34="",$D34=0),"",$C34/$D34) | F34: =IF($E34="","",REPT("█",MIN(10,ROUND($E34*10,0)))&REPT("░",MAX(0,10-ROUND($E34*10,0)))&IF($E34>1.049," +",""))
B35: =Vekt!C18 -> 35 | C35: =IF(Vekt!R18="","",Vekt!R18) | D35: =IF(Vekt!S18="","",Vekt!S18) | E35: =IF(OR($C35="",$D35="",$D35=0),"",$C35/$D35) | F35: =IF($E35="","",REPT("█",MIN(10,ROUND($E35*10,0)))&REPT("░",MAX(0,10-ROUND($E35*10,0)))&IF($E35>1.049," +",""))
B36: =Vekt!C19 -> 36 | C36: =IF(Vekt!R19="","",Vekt!R19) | D36: =IF(Vekt!S19="","",Vekt!S19) | E36: =IF(OR($C36="",$D36="",$D36=0),"",$C36/$D36) | F36: =IF($E36="","",REPT("█",MIN(10,ROUND($E36*10,0)))&REPT("░",MAX(0,10-ROUND($E36*10,0)))&IF($E36>1.049," +",""))
B37: =Vekt!C20 -> 37 | C37: =IF(Vekt!R20="","",Vekt!R20) | D37: =IF(Vekt!S20="","",Vekt!S20) | E37: =IF(OR($C37="",$D37="",$D37=0),"",$C37/$D37) | F37: =IF($E37="","",REPT("█",MIN(10,ROUND($E37*10,0)))&REPT("░",MAX(0,10-ROUND($E37*10,0)))&IF($E37>1.049," +",""))
B38: =Vekt!C21 -> 38 | C38: =IF(Vekt!R21="","",Vekt!R21) | D38: =IF(Vekt!S21="","",Vekt!S21) | E38: =IF(OR($C38="",$D38="",$D38=0),"",$C38/$D38) | F38: =IF($E38="","",REPT("█",MIN(10,ROUND($E38*10,0)))&REPT("░",MAX(0,10-ROUND($E38*10,0)))&IF($E38>1.049," +",""))
B39: =Vekt!C22 -> 39 | C39: =IF(Vekt!R22="","",Vekt!R22) | D39: =IF(Vekt!S22="","",Vekt!S22) | E39: =IF(OR($C39="",$D39="",$D39=0),"",$C39/$D39) | F39: =IF($E39="","",REPT("█",MIN(10,ROUND($E39*10,0)))&REPT("░",MAX(0,10-ROUND($E39*10,0)))&IF($E39>1.049," +",""))
B40: =Vekt!C23 -> 40 | C40: =IF(Vekt!R23="","",Vekt!R23) | D40: =IF(Vekt!S23="","",Vekt!S23) | E40: =IF(OR($C40="",$D40="",$D40=0),"",$C40/$D40) | F40: =IF($E40="","",REPT("█",MIN(10,ROUND($E40*10,0)))&REPT("░",MAX(0,10-ROUND($E40*10,0)))&IF($E40>1.049," +",""))
B41: =Vekt!C24 -> 41 | C41: =IF(Vekt!R24="","",Vekt!R24) | D41: =IF(Vekt!S24="","",Vekt!S24) | E41: =IF(OR($C41="",$D41="",$D41=0),"",$C41/$D41) | F41: =IF($E41="","",REPT("█",MIN(10,ROUND($E41*10,0)))&REPT("░",MAX(0,10-ROUND($E41*10,0)))&IF($E41>1.049," +",""))
B42: =Vekt!C25 -> 42 | C42: =IF(Vekt!R25="","",Vekt!R25) | D42: =IF(Vekt!S25="","",Vekt!S25) | E42: =IF(OR($C42="",$D42="",$D42=0),"",$C42/$D42) | F42: =IF($E42="","",REPT("█",MIN(10,ROUND($E42*10,0)))&REPT("░",MAX(0,10-ROUND($E42*10,0)))&IF($E42>1.049," +",""))
... B51: =Vekt!C34 -> 51 | C51: =IF(Vekt!R34="","",Vekt!R34) | D51: =IF(Vekt!S34="","",Vekt!S34) | E51: =IF(OR($C51="",$D51="",$D51=0),"",$C51/$D51) | F51: =IF($E51="","",REPT("█",MIN(10,ROUND($E51*10,0)))&REPT("░",MAX(0,10-ROUND($E51*10,0)))&IF($E51>1.049," +",""))
B52: TOTALT | C52: =IF(COUNT(C31:C51)=0,"",SUM(C31:C51)) -> 2100 | D52: =IF(COUNT(D31:D51)=0,"",SUM(D31:D51)) -> 2000 | E52: =IF(OR($C52="",$D52="",$D52=0),"",$C52/$D52) -> 1.05
B54: Alt på dette arket er formler som leser fra Dagslogg, Treningslogg, Vekt og Oversikt — ingen celler skal fylles inn her.
B55: Fargekonvensjonen i Guide §9 (grønn tekst = hentet fra annet ark) er bevisst fraveket på dette arket for lesbarhet.

Sheet Guide
B1: GUIDE — HELSE 2026
B2: Teknisk dokumentasjon av arbeidsboken. Les denne før du endrer noe. Sist oppdatert av Claude 28.07.2026.
B4: 1 · ARKOVERSIKT | C4: Sju ark: tre er inntastingsark (Dagslogg, Treningslogg, Styrketrening), tre er beregning og visning (Vekt, Oversikt, Kommentarer), ett er arkiv.
B5: Guide | C5: Dette arket. Ren dokumentasjon, ingen formler andre ark er avhengige av.
B6: Oversikt | C6: Visuell kalender uke 31–51: fargekodede dager etter treningsform. Kun formler + betinget formatering — leser fra Treningslogg. Ingen manuell inntasting.
B7: Vekt | C7: Kaloriunderskudd og vekttap per uke. Henter alle dagsdata fra Dagslogg. Manuell inntasting bare i forutsetningsblokken og MÅL/DAG-kolonnen.
B8: Dagslogg | C8: PRIMÆR INNTASTING for kropp/kalorier. Én rad per dag 27.07–20.12.2026. Brukeren fører Minus, Vekt, Vidde, Kommentar.
B9: Treningslogg | C9: PRIMÆR INNTASTING for trening. Én rad per økt. Styrkeøkter føres kort («Økt A/B/C») — detaljene ligger på Styrketrening.
B10: Styrketrening | C10: PRIMÆR INNTASTING for styrke. 30 øktblokker (fase 1, uke 31–40) med vekt/reps per sett og automatiske summer.
B11: Kommentarer | C11: Fotnoter (1)–(8) som øvelsesnavn viser til, samt beskrivelse av både gammelt og nåværende program.
B12: Styrketrening (historikk) | C12: ARKIV — RØR IKKE. Gammelt syklusprogram (16/8/4 RM) med loggede økter fra 2025. Beholdt for sammenligning av løft over tid.
B14: 2 · DATAFLYT | C14: Dagslogg ──(dato-oppslag)─→ Vekt (MINUS-celler, SNITTVEKT, SNITTVIDDE) ─→ status- og grafdata
C15: Treningslogg ──(dato + type)─→ Oversikt (cellefarge, fargebjelke, ØKTER, DAGER)
C16: Styrketrening står alene — ingen andre ark leser fra den. Treningslogg viser bare til den i tekst.
C17: Alle datoer stammer fra ÉN kilde: Vekt!$E$4 (startdato). Endre den, og hele arbeidsboken flytter seg.
B19: 3 · VEKT | C19: Forutsetninger B3:F7 — E4 startdato (27.07.2026), E5 startvekt (77,45), E6 startlivvidde (90), E7 kcal per kg (7500). Alt annet refererer hit; ingen av disse tallene skal hardkodes i formler.
C20: Status R3:U10 — underskudd hittil, måloppnåelse %, estimert tap, faktisk tap, livvidde-reduksjon, totalt mål, fremskrevet sluttresultat. Alle formler.
C21: Matrise rad 13 = kolonneoverskrift. Rad 14–34 = uke 31–51 (én rad per uke). Rad 35 = TOTALT.
C22: Kolonner: B måned · C uke · D:Q sju dagpar (DATO/MINUS) · R SUM UKE · S UKEMÅL · T MÅL/DAG (eneste inputkolonne, 1000→600 kcal) · U EST. TAP · V EST. VEKT · W SNITTVEKT · X AVVIK · Y SNITTVIDDE.
C23: MINUS-cellene er IKKE input: =IF(COUNTIFS(Dagslogg[Dato];dato;Dagslogg[Minus];"<>")=0;"";SUMIFS(...)) — tom hvis dagen ikke er logget, 0 hvis 0 er logget.
C24: SNITTVEKT/SNITTVIDDE = AVERAGEIFS over ukens sju datoer — snitt kun over de dagene som faktisk er målt (delvis uke håndteres riktig).
C25: UKEMÅL = MÅL/DAG × antall loggede dager i uken. EST. TAP = SUM UKE / E7. Frosne ruter: A1:C13. Grafdata i Z25:AB47 (NA() for ulogget uke) — ikke rediger.
B27: 4 · DAGSLOGG | C27: Excel-tabell «Dagslogg», område A3:G150. Kolonner: Dato · Uke · Ukedag · Minus · Vekt · Vidde · Kommentar.
C28: Rad 4–150 = 147 dager, 27.07–20.12.2026. Dato/Uke/Ukedag er formler (=Vekt!$E$4+ROW()-4, ISOWEEKNUM, TEXT). Minus/Vekt/Vidde/Kommentar er input.
C29: Dagens rad markeres av betinget formatering (=$A4=TODAY()). Frosne ruter: rad 1–3. Bruk strukturerte referanser (Dagslogg[Kolonne]) i nye formler.
B31: 5 · TRENINGSLOGG | C31: Excel-tabell «Treningslogg», område A3:G203. Kolonner: Dato · Type · Beskrivelse · Varighet (min) · Distanse (km) · Intensitet · Kommentar.
C32: Type har nedtrekksliste med presis ordlyd: Styrketrening, Løping, Sykling, Svømming, Karate, Klatring, Annet. Oversikt matcher på EKSAKT denne teksten — endres et navn, må alle 13 regler på Oversikt oppdateres.
C33: Intensitet har nedtrekk: Rolig (sone 2), Terskel, Hard, Blandet. Flere økter samme dag = flere rader med samme dato (det er meningen).
B35: 6 · OVERSIKT | C35: Kalender B5:L47. TO RADER PER UKE: hovedrad (like radnr, 22 pkt, viser dagtall) + bjelkerad rett under (odde radnr, 7 pkt, innhold skjult med format ";;;").
C36: Uke nr. n ligger i rad 6+2n regnet fra uke 31 (uke 31 = rad 6–7, uke 32 = rad 8–9 osv.). Kolonner: B måned · C uke · D:J MAN–SØN · K ØKTER · L DAGER. B/C/K/L er sammenslått over de to radene per uke.
C37: 13 betingede formateringsregler på D6:J47: 6 bjelkeregler (ISODD(ROW()) + type finnes + type høyere i listen finnes) først, deretter 7 fyllregler (ISEVEN(ROW()) + type finnes). Alle stopIfTrue=true, prioritet 0–12 i legendrekkefølge.
C38: Hovedfarge = første treningsform i legendrekkefølgen som finnes den dagen. Bjelken = nummer to. Ved tre eller flere typer vises fortsatt bare nr. 2.
C39: Tegnforklaring N5:O28 — ligger bevisst bare på hovedrader (like radnr), ellers klippes teksten av de 7 punkts bjelkeradene.
B41: 7 · STYRKETRENING | C41: 30 øktblokker for fase 1 (uke 31–40 × 3 økter). Blokk nr. b starter i rad 10 + b×12, der b = (uke−31)×3 + økt (Økt A=0, B=1, C=2). Første blokk rad 10–20, siste rad 358–368.
C42: Radmønster innen en blokk (offset fra blokkstart): +0 økttittel · +1 øvelsesnavn · +2 dato + mål (sett×reps) · +3 Vekt/Reps-etiketter · +4 Oppvarming · +5 til +8 Sett 1–4 · +9 Sum · +10 Kommentar.
C43: Kolonner: B etiketter · C:N seks øvelsespar (Vekt/Reps) · O totalsum. Økt C bruker bare fire øvelser — K:N er grået ut der.
C44: SUM-LOGIKK (arvet fra historikk-arket, skal ikke endres): øvelsessum = SUMPRODUCT(vekt; reps). Lette/høyreps-øvelser merket (6) ganges med 0,25 så de ikke blåser opp totalen. O-kolonnen summerer per sett-rad med samme 0,25-faktor, og O(+9) = SUM av sett-radene.
C45: Øvelser med 0,25-faktor i fase 1: Sidehev, Hengende beinhev, Facepulls, Pallof-press. Kroppsvektsøvelser (Pullups, Chins, Dips) føres med kroppsvekt + evt. tillegg i vektfeltet — se fotnote (7).
C46: Uke 31 inneholder forslag til startvekter i KURSIV ORANSJE (#C55A11) med notat om begrunnelsen. Kursiv oransje = forslag, ikke logget data. Blå tekst = brukerens input.
C47: GJENSTÅR: bare fase 1 er bygget. Fase 2 (uke 41+, etter vedlikeholdspause 1) må legges til når programmet er justert — bygg videre med samme blokkformel (rad 10+b×12).
...

Sheet Oversikt
B1: TRENINGSOVERSIKT — HØST 2026
B2: Farge = treningsform (fra Treningslogg). Tom celle = hviledag.
B5: MÅNED | C5: UKE | D5: MAN | E5: TIR | F5: ONS | G5: TOR | H5: FRE | I5: LØR | J5: SØN | K5: ØKTER | L5: DAGER | N5: TEGNFORKLARING
B6: =IF(OR(ROW()=6,MONTH(D6)<>MONTH(D6-7)),PROPER(TEXT(D6,"mmmm")),"") -> Juli | C6: =_xlfn.ISOWEEKNUM(D6) -> 31 | D6: =Vekt!$E$4 -> 46230 | E6: =D6+1 -> 46231 | F6: =D6+2 -> 46232 | G6: =D6+3 -> 46233 | H6: =D6+4 -> 46234 | I6: =D6+5 -> 46235 | J6: =D6+6 -> 46236 | K6: =COUNTIFS(Treningslogg!$A:$A,">="&D6,Treningslogg!$A:$A,"<="&J6) -> 11 | L6: {=SUMPRODUCT(--(COUNTIF(Treningslogg!$A:$A,D6:J6)>0))} -> 7 | O6: Styrketrening
D7: =D6 -> 46230 | E7: =E6 -> 46231 | F7: =F6 -> 46232 | G7: =G6 -> 46233 | H7: =H6 -> 46234 | I7: =I6 -> 46235 | J7: =J6 -> 46236
B8: =IF(OR(ROW()=6,MONTH(D8)<>MONTH(D8-7)),PROPER(TEXT(D8,"mmmm")),"") -> August | C8: =_xlfn.ISOWEEKNUM(D8) -> 32 | D8: =D6+7 -> 46237 | E8: =D8+1 -> 46238 | F8: =D8+2 -> 46239 | G8: =D8+3 -> 46240 | H8: =D8+4 -> 46241 | I8: =D8+5 -> 46242 | J8: =D8+6 -> 46243 | K8: =COUNTIFS(Treningslogg!$A:$A,">="&D8,Treningslogg!$A:$A,"<="&J8) -> 0 | L8: {=SUMPRODUCT(--(COUNTIF(Treningslogg!$A:$A,D8:J8)>0))} -> 0 | O8: Løping
D9: =D8 -> 46237 | E9: =E8 -> 46238 | F9: =F8 -> 46239 | G9: =G8 -> 46240 | H9: =H8 -> 46241 | I9: =I8 -> 46242 | J9: =J8 -> 46243
B10: =IF(OR(ROW()=6,MONTH(D10)<>MONTH(D10-7)),PROPER(TEXT(D10,"mmmm")),"") | C10: =_xlfn.ISOWEEKNUM(D10) -> 33 | D10: =D8+7 -> 46244 | E10: =D10+1 -> 46245 | F10: =D10+2 -> 46246 | G10: =D10+3 -> 46247 | H10: =D10+4 -> 46248 | I10: =D10+5 -> 46249 | J10: =D10+6 -> 46250 | K10: =COUNTIFS(Treningslogg!$A:$A,">="&D10,Treningslogg!$A:$A,"<="&J10) -> 0 | L10: {=SUMPRODUCT(--(COUNTIF(Treningslogg!$A:$A,D10:J10)>0))} -> 0 | O10: Sykling
D11: =D10 -> 46244 | E11: =E10 -> 46245 | F11: =F10 -> 46246 | G11: =G10 -> 46247 | H11: =H10 -> 46248 | I11: =I10 -> 46249 | J11: =J10 -> 46250
B12: =IF(OR(ROW()=6,MONTH(D12)<>MONTH(D12-7)),PROPER(TEXT(D12,"mmmm")),"") | C12: =_xlfn.ISOWEEKNUM(D12) -> 34 | D12: =D10+7 -> 46251 | E12: =D12+1 -> 46252 | F12: =D12+2 -> 46253 | G12: =D12+3 -> 46254 | H12: =D12+4 -> 46255 | I12: =D12+5 -> 46256 | J12: =D12+6 -> 46257 | K12: =COUNTIFS(Treningslogg!$A:$A,">="&D12,Treningslogg!$A:$A,"<="&J12) -> 0 | L12: {=SUMPRODUCT(--(COUNTIF(Treningslogg!$A:$A,D12:J12)>0))} -> 0 | O12: Svømming
D13: =D12 -> 46251 | E13: =E12 -> 46252 | F13: =F12 -> 46253 | G13: =G12 -> 46254 | H13: =H12 -> 46255 | I13: =I12 -> 46256 | J13: =J12 -> 46257
B14: =IF(OR(ROW()=6,MONTH(D14)<>MONTH(D14-7)),PROPER(TEXT(D14,"mmmm")),"") | C14: =_xlfn.ISOWEEKNUM(D14) -> 35 | D14: =D12+7 -> 46258 | E14: =D14+1 -> 46259 | F14: =D14+2 -> 46260 | G14: =D14+3 -> 46261 | H14: =D14+4 -> 46262 | I14: =D14+5 -> 46263 | J14: =D14+6 -> 46264 | K14: =COUNTIFS(Treningslogg!$A:$A,">="&D14,Treningslogg!$A:$A,"<="&J14) -> 0 | L14: {=SUMPRODUCT(--(COUNTIF(Treningslogg!$A:$A,D14:J14)>0))} -> 0 | O14: Karate
D15: =D14 -> 46258 | E15: =E14 -> 46259 | F15: =F14 -> 46260 | G15: =G14 -> 46261 | H15: =H14 -> 46262 | I15: =I14 -> 46263 | J15: =J14 -> 46264
B16: =IF(OR(ROW()=6,MONTH(D16)<>MONTH(D16-7)),PROPER(TEXT(D16,"mmmm")),"") | C16: =_xlfn.ISOWEEKNUM(D16) -> 36 | D16: =D14+7 -> 46265 | E16: =D16+1 -> 46266 | F16: =D16+2 -> 46267 | G16: =D16+3 -> 46268 | H16: =D16+4 -> 46269 | I16: =D16+5 -> 46270 | J16: =D16+6 -> 46271 | K16: =COUNTIFS(Treningslogg!$A:$A,">="&D16,Treningslogg!$A:$A,"<="&J16) -> 0 | L16: {=SUMPRODUCT(--(COUNTIF(Treningslogg!$A:$A,D16:J16)>0))} -> 0 | O16: Klatring
D17: =D16 -> 46265 | E17: =E16 -> 46266 | F17: =F16 -> 46267 | G17: =G16 -> 46268 | H17: =H16 -> 46269 | I17: =I16 -> 46270 | J17: =J16 -> 46271
B18: =IF(OR(ROW()=6,MONTH(D18)<>MONTH(D18-7)),PROPER(TEXT(D18,"mmmm")),"") -> September | C18: =_xlfn.ISOWEEKNUM(D18) -> 37 | D18: =D16+7 -> 46272 | E18: =D18+1 -> 46273 | F18: =D18+2 -> 46274 | G18: =D18+3 -> 46275 | H18: =D18+4 -> 46276 | I18: =D18+5 -> 46277 | J18: =D18+6 -> 46278 | K18: =COUNTIFS(Treningslogg!$A:$A,">="&D18,Treningslogg!$A:$A,"<="&J18) -> 0 | L18: {=SUMPRODUCT(--(COUNTIF(Treningslogg!$A:$A,D18:J18)>0))} -> 0 | O18: Annet
D19: =D18 -> 46272 | E19: =E18 -> 46273 | F19: =F18 -> 46274 | G19: =G18 -> 46275 | H19: =H18 -> 46276 | I19: =I18 -> 46277 | J19: =J18 -> 46278
B20: =IF(OR(ROW()=6,MONTH(D20)<>MONTH(D20-7)),PROPER(TEXT(D20,"mmmm")),"") | C20: =_xlfn.ISOWEEKNUM(D20) -> 38 | D20: =D18+7 -> 46279 | E20: =D20+1 -> 46280 | F20: =D20+2 -> 46281 | G20: =D20+3 -> 46282 | H20: =D20+4 -> 46283 | I20: =D20+5 -> 46284 | J20: =D20+6 -> 46285 | K20: =COUNTIFS(Treningslogg!$A:$A,">="&D20,Treningslogg!$A:$A,"<="&J20) -> 0 | L20: {=SUMPRODUCT(--(COUNTIF(Treningslogg!$A:$A,D20:J20)>0))} -> 0 | N20: tom celle | O20: hviledag
D21: =D20 -> 46279 | E21: =E20 -> 46280 | F21: =F20 -> 46281 | G21: =G20 -> 46282 | H21: =H20 -> 46283 | I21: =I20 -> 46284 | J21: =J20 -> 46285
B22: =IF(OR(ROW()=6,MONTH(D22)<>MONTH(D22-7)),PROPER(TEXT(D22,"mmmm")),"") | C22: =_xlfn.ISOWEEKNUM(D22) -> 39 | D22: =D20+7 -> 46286 | E22: =D22+1 -> 46287 | F22: =D22+2 -> 46288 | G22: =D22+3 -> 46289 | H22: =D22+4 -> 46290 | I22: =D22+5 -> 46291 | J22: =D22+6 -> 46292 | K22: =COUNTIFS(Treningslogg!$A:$A,">="&D22,Treningslogg!$A:$A,"<="&J22) -> 0 | L22: {=SUMPRODUCT(--(COUNTIF(Treningslogg!$A:$A,D22:J22)>0))} -> 0 | N22: ▄ | O22: fargebjelke under dagen = andre økttype samme dag
D23: =D22 -> 46286 | E23: =E22 -> 46287 | F23: =F22 -> 46288 | G23: =G22 -> 46289 | H23: =H22 -> 46290 | I23: =I22 -> 46291 | J23: =J22 -> 46292
B24: =IF(OR(ROW()=6,MONTH(D24)<>MONTH(D24-7)),PROPER(TEXT(D24,"mmmm")),"") | C24: =_xlfn.ISOWEEKNUM(D24) -> 40 | D24: =D22+7 -> 46293 | E24: =D24+1 -> 46294 | F24: =D24+2 -> 46295 | G24: =D24+3 -> 46296 | H24: =D24+4 -> 46297 | I24: =D24+5 -> 46298 | J24: =D24+6 -> 46299 | K24: =COUNTIFS(Treningslogg!$A:$A,">="&D24,Treningslogg!$A:$A,"<="&J24) -> 0 | L24: {=SUMPRODUCT(--(COUNTIF(Treningslogg!$A:$A,D24:J24)>0))} -> 0 | O24: flere enn to typer: bjelken viser type nr. 2 i listen over
D25: =D24 -> 46293 | E25: =E24 -> 46294 | F25: =F24 -> 46295 | G25: =G24 -> 46296 | H25: =H24 -> 46297 | I25: =I24 -> 46298 | J25: =J24 -> 46299
B26: =IF(OR(ROW()=6,MONTH(D26)<>MONTH(D26-7)),PROPER(TEXT(D26,"mmmm")),"") -> Oktober | C26: =_xlfn.ISOWEEKNUM(D26) -> 41 | D26: =D24+7 -> 46300 | E26: =D26+1 -> 46301 | F26: =D26+2 -> 46302 | G26: =D26+3 -> 46303 | H26: =D26+4 -> 46304 | I26: =D26+5 -> 46305 | J26: =D26+6 -> 46306 | K26: =COUNTIFS(Treningslogg!$A:$A,">="&D26,Treningslogg!$A:$A,"<="&J26) -> 0 | L26: {=SUMPRODUCT(--(COUNTIF(Treningslogg!$A:$A,D26:J26)>0))} -> 0
D27: =D26 -> 46300 | E27: =E26 -> 46301 | F27: =F26 -> 46302 | G27: =G26 -> 46303 | H27: =H26 -> 46304 | I27: =I26 -> 46305 | J27: =J26 -> 46306
B28: =IF(OR(ROW()=6,MONTH(D28)<>MONTH(D28-7)),PROPER(TEXT(D28,"mmmm")),"") | C28: =_xlfn.ISOWEEKNUM(D28) -> 42 | D28: =D26+7 -> 46307 | E28: =D28+1 -> 46308 | F28: =D28+2 -> 46309 | G28: =D28+3 -> 46310 | H28: =D28+4 -> 46311 | I28: =D28+5 -> 46312 | J28: =D28+6 -> 46313 | K28: =COUNTIFS(Treningslogg!$A:$A,">="&D28,Treningslogg!$A:$A,"<="&J28) -> 0 | L28: {=SUMPRODUCT(--(COUNTIF(Treningslogg!$A:$A,D28:J28)>0))} -> 0 | N28: DEMO | O28: Uke 31 er fylt med demo-økter. Slett DEMO-radene i Treningslogg for å nullstille.
D29: =D28 -> 46307 | E29: =E28 -> 46308 | F29: =F28 -> 46309 | G29: =G28 -> 46310 | H29: =H28 -> 46311 | I29: =I28 -> 46312 | J29: =J28 -> 46313
B30: =IF(OR(ROW()=6,MONTH(D30)<>MONTH(D30-7)),PROPER(TEXT(D30,"mmmm")),"") | C30: =_xlfn.ISOWEEKNUM(D30) -> 43 | D30: =D28+7 -> 46314 | E30: =D30+1 -> 46315 | F30: =D30+2 -> 46316 | G30: =D30+3 -> 46317 | H30: =D30+4 -> 46318 | I30: =D30+5 -> 46319 | J30: =D30+6 -> 46320 | K30: =COUNTIFS(Treningslogg!$A:$A,">="&D30,Treningslogg!$A:$A,"<="&J30) -> 0 | L30: {=SUMPRODUCT(--(COUNTIF(Treningslogg!$A:$A,D30:J30)>0))} -> 0
D31: =D30 -> 46314 | E31: =E30 -> 46315 | F31: =F30 -> 46316 | G31: =G30 -> 46317 | H31: =H30 -> 46318 | I31: =I30 -> 46319 | J31: =J30 -> 46320
B32: =IF(OR(ROW()=6,MONTH(D32)<>MONTH(D32-7)),PROPER(TEXT(D32,"mmmm")),"") | C32: =_xlfn.ISOWEEKNUM(D32) -> 44 | D32: =D30+7 -> 46321 | E32: =D32+1 -> 46322 | F32: =D32+2 -> 46323 | G32: =D32+3 -> 46324 | H32: =D32+4 -> 46325 | I32: =D32+5 -> 46326 | J32: =D32+6 -> 46327 | K32: =COUNTIFS(Treningslogg!$A:$A,">="&D32,Treningslogg!$A:$A,"<="&J32) -> 0 | L32: {=SUMPRODUCT(--(COUNTIF(Treningslogg!$A:$A,D32:J32)>0))} -> 0
D33: =D32 -> 46321 | E33: =E32 -> 46322 | F33: =F32 -> 46323 | G33: =G32 -> 46324 | H33: =H32 -> 46325 | I33: =I32 -> 46326 | J33: =J32 -> 46327
B34: =IF(OR(ROW()=6,MONTH(D34)<>MONTH(D34-7)),PROPER(TEXT(D34,"mmmm")),"") -> November | C34: =_xlfn.ISOWEEKNUM(D34) -> 45 | D34: =D32+7 -> 46328 | E34: =D34+1 -> 46329 | F34: =D34+2 -> 46330 | G34: =D34+3 -> 46331 | H34: =D34+4 -> 46332 | I34: =D34+5 -> 46333 | J34: =D34+6 -> 46334 | K34: =COUNTIFS(Treningslogg!$A:$A,">="&D34,Treningslogg!$A:$A,"<="&J34) -> 0 | L34: {=SUMPRODUCT(--(COUNTIF(Treningslogg!$A:$A,D34:J34)>0))} -> 0
D35: =D34 -> 46328 | E35: =E34 -> 46329 | F35: =F34 -> 46330 | G35: =G34 -> 46331 | H35: =H34 -> 46332 | I35: =I34 -> 46333 | J35: =J34 -> 46334
B36: =IF(OR(ROW()=6,MONTH(D36)<>MONTH(D36-7)),PROPER(TEXT(D36,"mmmm")),"") | C36: =_xlfn.ISOWEEKNUM(D36) -> 46 | D36: =D34+7 -> 46335 | E36: =D36+1 -> 46336 | F36: =D36+2 -> 46337 | G36: =D36+3 -> 46338 | H36: =D36+4 -> 46339 | I36: =D36+5 -> 46340 | J36: =D36+6 -> 46341 | K36: =COUNTIFS(Treningslogg!$A:$A,">="&D36,Treningslogg!$A:$A,"<="&J36) -> 0 | L36: {=SUMPRODUCT(--(COUNTIF(Treningslogg!$A:$A,D36:J36)>0))} -> 0
D37: =D36 -> 46335 | E37: =E36 -> 46336 | F37: =F36 -> 46337 | G37: =G36 -> 46338 | H37: =H36 -> 46339 | I37: =I36 -> 46340 | J37: =J36 -> 46341
B38: =IF(OR(ROW()=6,MONTH(D38)<>MONTH(D38-7)),PROPER(TEXT(D38,"mmmm")),"") | C38: =_xlfn.ISOWEEKNUM(D38) -> 47 | D38: =D36+7 -> 46342 | E38: =D38+1 -> 46343 | F38: =D38+2 -> 46344 | G38: =D38+3 -> 46345 | H38: =D38+4 -> 46346 | I38: =D38+5 -> 46347 | J38: =D38+6 -> 46348 | K38: =COUNTIFS(Treningslogg!$A:$A,">="&D38,Treningslogg!$A:$A,"<="&J38) -> 0 | L38: {=SUMPRODUCT(--(COUNTIF(Treningslogg!$A:$A,D38:J38)>0))} -> 0
D39: =D38 -> 46342 | E39: =E38 -> 46343 | F39: =F38 -> 46344 | G39: =G38 -> 46345 | H39: =H38 -> 46346 | I39: =I38 -> 46347 | J39: =J38 -> 46348
B40: =IF(OR(ROW()=6,MONTH(D40)<>MONTH(D40-7)),PROPER(TEXT(D40,"mmmm")),"") | C40: =_xlfn.ISOWEEKNUM(D40) -> 48 | D40: =D38+7 -> 46349 | E40: =D40+1 -> 46350 | F40: =D40+2 -> 46351 | G40: =D40+3 -> 46352 | H40: =D40+4 -> 46353 | I40: =D40+5 -> 46354 | J40: =D40+6 -> 46355 | K40: =COUNTIFS(Treningslogg!$A:$A,">="&D40,Treningslogg!$A:$A,"<="&J40) -> 0 | L40: {=SUMPRODUCT(--(COUNTIF(Treningslogg!$A:$A,D40:J40)>0))} -> 0
D41: =D40 -> 46349 | E41: =E40 -> 46350 | F41: =F40 -> 46351 | G41: =G40 -> 46352 | H41: =H40 -> 46353 | I41: =I40 -> 46354 | J41: =J40 -> 46355
B42: =IF(OR(ROW()=6,MONTH(D42)<>MONTH(D42-7)),PROPER(TEXT(D42,"mmmm")),"") | C42: =_xlfn.ISOWEEKNUM(D42) -> 49 | D42: =D40+7 -> 46356 | E42: =D42+1 -> 46357 | F42: =D42+2 -> 46358 | G42: =D42+3 -> 46359 | H42: =D42+4 -> 46360 | I42: =D42+5 -> 46361 | J42: =D42+6 -> 46362 | K42: =COUNTIFS(Treningslogg!$A:$A,">="&D42,Treningslogg!$A:$A,"<="&J42) -> 0 | L42: {=SUMPRODUCT(--(COUNTIF(Treningslogg!$A:$A,D42:J42)>0))} -> 0
...

Sheet Vekt
B1: VEKT & KALORIUNDERSKUDD — HØST 2026
B2: Netto kaloriunderskudd per dag → estimert vs. faktisk vekttap. Alle dagsdata føres i Dagslogg.
B3: FORUTSETNINGER | R3: STATUS
B4: Startdato (mandag uke 31) | E4: 46230 | R4: Underskudd hittil (kcal) | U4: =SUM($R$14:$R$34) -> 2100
B5: Startvekt (kg) | E5: 77.45 | R5: Måloppnåelse hittil | U5: =IFERROR(U4/SUM($S$14:$S$34),"") -> 1.05
B6: Startlivvidde (cm) | E6: 90 | R6: Estimert tap hittil (kg) | U6: =SUM($U$14:$U$34) -> 0.28
B7: Kcal per kg kroppsvekt | E7: 7500 | R7: Faktisk tap hittil (kg) | U7: {=IFERROR($E$5-LOOKUP(2,1/($W$14:$W$34<>""),$W$14:$W$34),"")} -> -0.05
R8: Livvidde-reduksjon (cm) | U8: {=IFERROR($E$6-LOOKUP(2,1/($Y$14:$Y$34<>""),$Y$14:$Y$34),"")} -> 1.25
R9: Totalt mål (kg) | U9: =7*SUM($T$14:$T$34)/$E$7 -> 15.866667
R10: Fremskrevet sluttresultat (kg) | U10: =IFERROR(U5*U9,"") -> 16.66
B12: MÅNED / UKE | D12: MANDAG | F12: TIRSDAG | H12: ONSDAG | J12: TORSDAG | L12: FREDAG | N12: LØRDAG | P12: SØNDAG | R12: KALORIER (KCAL) | U12: VEKT (KG) | Y12: VIDDE (CM)
B13: MÅNED | C13: UKE | D13: DATO | E13: MINUS | F13: DATO | G13: MINUS | H13: DATO | I13: MINUS | J13: DATO | K13: MINUS | L13: DATO | M13: MINUS | N13: DATO | O13: MINUS | P13: DATO | Q13: MINUS | R13: SUM UKE | S13: UKEMÅL | T13: MÅL/DAG | U13: EST. TAP | V13: EST. VEKT | W13: SNITTVEKT | X13: AVVIK | Y13: SNITTVIDDE
B14: JULI | C14: 31 | D14: =$E$4 -> 46230 | E14: =IF(COUNTIFS(Dagslogg[Dato],D14,Dagslogg[Minus],"<>")=0,"",SUMIFS(Dagslogg[Minus],Dagslogg[Dato],D14)) | F14: =D14+1 -> 46231 | G14: =IF(COUNTIFS(Dagslogg[Dato],F14,Dagslogg[Minus],"<>")=0,"",SUMIFS(Dagslogg[Minus],Dagslogg[Dato],F14)) -> 1000 | H14: =F14+1 -> 46232 | I14: =IF(COUNTIFS(Dagslogg[Dato],H14,Dagslogg[Minus],"<>")=0,"",SUMIFS(Dagslogg[Minus],Dagslogg[Dato],H14)) -> 1100 | J14: =H14+1 -> 46233 | K14: =IF(COUNTIFS(Dagslogg[Dato],J14,Dagslogg[Minus],"<>")=0,"",SUMIFS(Dagslogg[Minus],Dagslogg[Dato],J14)) | L14: =J14+1 -> 46234 | M14: =IF(COUNTIFS(Dagslogg[Dato],L14,Dagslogg[Minus],"<>")=0,"",SUMIFS(Dagslogg[Minus],Dagslogg[Dato],L14)) | N14: =L14+1 -> 46235 | O14: =IF(COUNTIFS(Dagslogg[Dato],N14,Dagslogg[Minus],"<>")=0,"",SUMIFS(Dagslogg[Minus],Dagslogg[Dato],N14)) | P14: =N14+1 -> 46236 | Q14: =IF(COUNTIFS(Dagslogg[Dato],P14,Dagslogg[Minus],"<>")=0,"",SUMIFS(Dagslogg[Minus],Dagslogg[Dato],P14)) | R14: =IF(COUNT(E14,G14,I14,K14,M14,O14,Q14)=0,"",SUM(E14,G14,I14,K14,M14,O14,Q14)) -> 2100 | S14: =IF(R14="","",T14*COUNT(E14,G14,I14,K14,M14,O14,Q14)) -> 2000 | T14: 1000 | U14: =IF(R14="","",R14/$E$7) -> 0.28 | V14: =IF(R14="","",$E$5-SUM($U$14:U14)) -> 77.17 | W14: =IFERROR(AVERAGEIFS(Dagslogg[Vekt],Dagslogg[Dato],">="&D14,Dagslogg[Dato],"<="&D14+6),"") -> 77.5 | X14: =IF(OR(W14="",V14=""),"",W14-V14) -> 0.33 | Y14: =IFERROR(AVERAGEIFS(Dagslogg[Vidde],Dagslogg[Dato],">="&D14,Dagslogg[Dato],"<="&D14+6),"") -> 88.75
B15: AUGUST | C15: =C14+1 -> 32 | D15: =D14+7 -> 46237 | E15: =IF(COUNTIFS(Dagslogg[Dato],D15,Dagslogg[Minus],"<>")=0,"",SUMIFS(Dagslogg[Minus],Dagslogg[Dato],D15)) | F15: =D15+1 -> 46238 | G15: =IF(COUNTIFS(Dagslogg[Dato],F15,Dagslogg[Minus],"<>")=0,"",SUMIFS(Dagslogg[Minus],Dagslogg[Dato],F15)) | H15: =F15+1 -> 46239 | I15: =IF(COUNTIFS(Dagslogg[Dato],H15,Dagslogg[Minus],"<>")=0,"",SUMIFS(Dagslogg[Minus],Dagslogg[Dato],H15)) | J15: =H15+1 -> 46240 | K15: =IF(COUNTIFS(Dagslogg[Dato],J15,Dagslogg[Minus],"<>")=0,"",SUMIFS(Dagslogg[Minus],Dagslogg[Dato],J15)) | L15: =J15+1 -> 46241 | M15: =IF(COUNTIFS(Dagslogg[Dato],L15,Dagslogg[Minus],"<>")=0,"",SUMIFS(Dagslogg[Minus],Dagslogg[Dato],L15)) | N15: =L15+1 -> 46242 | O15: =IF(COUNTIFS(Dagslogg[Dato],N15,Dagslogg[Minus],"<>")=0,"",SUMIFS(Dagslogg[Minus],Dagslogg[Dato],N15)) | P15: =N15+1 -> 46243 | Q15: =IF(COUNTIFS(Dagslogg[Dato],P15,Dagslogg[Minus],"<>")=0,"",SUMIFS(Dagslogg[Minus],Dagslogg[Dato],P15)) | R15: =IF(COUNT(E15,G15,I15,K15,M15,O15,Q15)=0,"",SUM(E15,G15,I15,K15,M15,O15,Q15)) | S15: =IF(R15="","",T15*COUNT(E15,G15,I15,K15,M15,O15,Q15)) | T15: 1000 | U15: =IF(R15="","",R15/$E$7) | V15: =IF(R15="","",$E$5-SUM($U$14:U15)) | W15: =IFERROR(AVERAGEIFS(Dagslogg[Vekt],Dagslogg[Dato],">="&D15,Dagslogg[Dato],"<="&D15+6),"") | X15: =IF(OR(W15="",V15=""),"",W15-V15) | Y15: =IFERROR(AVERAGEIFS(Dagslogg[Vidde],Dagslogg[Dato],">="&D15,Dagslogg[Dato],"<="&D15+6),"")
C16: =C15+1 -> 33 | D16: =D15+7 -> 46244 | E16: =IF(COUNTIFS(Dagslogg[Dato],D16,Dagslogg[Minus],"<>")=0,"",SUMIFS(Dagslogg[Minus],Dagslogg[Dato],D16)) | F16: =D16+1 -> 46245 | G16: =IF(COUNTIFS(Dagslogg[Dato],F16,Dagslogg[Minus],"<>")=0,"",SUMIFS(Dagslogg[Minus],Dagslogg[Dato],F16)) | H16: =F16+1 -> 46246 | I16: =IF(COUNTIFS(Dagslogg[Dato],H16,Dagslogg[Minus],"<>")=0,"",SUMIFS(Dagslogg[Minus],Dagslogg[Dato],H16)) | J16: =H16+1 -> 46247 | K16: =IF(COUNTIFS(Dagslogg[Dato],J16,Dagslogg[Minus],"<>")=0,"",SUMIFS(Dagslogg[Minus],Dagslogg[Dato],J16)) | L16: =J16+1 -> 46248 | M16: =IF(COUNTIFS(Dagslogg[Dato],L16,Dagslogg[Minus],"<>")=0,"",SUMIFS(Dagslogg[Minus],Dagslogg[Dato],L16)) | N16: =L16+1 -> 46249 | O16: =IF(COUNTIFS(Dagslogg[Dato],N16,Dagslogg[Minus],"<>")=0,"",SUMIFS(Dagslogg[Minus],Dagslogg[Dato],N16)) | P16: =N16+1 -> 46250 | Q16: =IF(COUNTIFS(Dagslogg[Dato],P16,Dagslogg[Minus],"<>")=0,"",SUMIFS(Dagslogg[Minus],Dagslogg[Dato],P16)) | R16: =IF(COUNT(E16,G16,I16,K16,M16,O16,Q16)=0,"",SUM(E16,G16,I16,K16,M16,O16,Q16)) | S16: =IF(R16="","",T16*COUNT(E16,G16,I16,K16,M16,O16,Q16)) | T16: 1000 | U16: =IF(R16="","",R16/$E$7) | V16: =IF(R16="","",$E$5-SUM($U$14:U16)) | W16: =IFERROR(AVERAGEIFS(Dagslogg[Vekt],Dagslogg[Dato],">="&D16,Dagslogg[Dato],"<="&D16+6),"") | X16: =IF(OR(W16="",V16=""),"",W16-V16) | Y16: =IFERROR(AVERAGEIFS(Dagslogg[Vidde],Dagslogg[Dato],">="&D16,Dagslogg[Dato],"<="&D16+6),"")
C17: =C16+1 -> 34 | D17: =D16+7 -> 46251 | E17: =IF(COUNTIFS(Dagslogg[Dato],D17,Dagslogg[Minus],"<>")=0,"",SUMIFS(Dagslogg[Minus],Dagslogg[Dato],D17)) | F17: =D17+1 -> 46252 | G17: =IF(COUNTIFS(Dagslogg[Dato],F17,Dagslogg[Minus],"<>")=0,"",SUMIFS(Dagslogg[Minus],Dagslogg[Dato],F17)) | H17: =F17+1 -> 46253 | I17: =IF(COUNTIFS(Dagslogg[Dato],H17,Dagslogg[Minus],"<>")=0,"",SUMIFS(Dagslogg[Minus],Dagslogg[Dato],H17)) | J17: =H17+1 -> 46254 | K17: =IF(COUNTIFS(Dagslogg[Dato],J17,Dagslogg[Minus],"<>")=0,"",SUMIFS(Dagslogg[Minus],Dagslogg[Dato],J17)) | L17: =J17+1 -> 46255 | M17: =IF(COUNTIFS(Dagslogg[Dato],L17,Dagslogg[Minus],"<>")=0,"",SUMIFS(Dagslogg[Minus],Dagslogg[Dato],L17)) | N17: =L17+1 -> 46256 | O17: =IF(COUNTIFS(Dagslogg[Dato],N17,Dagslogg[Minus],"<>")=0,"",SUMIFS(Dagslogg[Minus],Dagslogg[Dato],N17)) | P17: =N17+1 -> 46257 | Q17: =IF(COUNTIFS(Dagslogg[Dato],P17,Dagslogg[Minus],"<>")=0,"",SUMIFS(Dagslogg[Minus],Dagslogg[Dato],P17)) | R17: =IF(COUNT(E17,G17,I17,K17,M17,O17,Q17)=0,"",SUM(E17,G17,I17,K17,M17,O17,Q17)) | S17: =IF(R17="","",T17*COUNT(E17,G17,I17,K17,M17,O17,Q17)) | T17: 1000 | U17: =IF(R17="","",R17/$E$7) | V17: =IF(R17="","",$E$5-SUM($U$14:U17)) | W17: =IFERROR(AVERAGEIFS(Dagslogg[Vekt],Dagslogg[Dato],">="&D17,Dagslogg[Dato],"<="&D17+6),"") | X17: =IF(OR(W17="",V17=""),"",W17-V17) | Y17: =IFERROR(AVERAGEIFS(Dagslogg[Vidde],Dagslogg[Dato],">="&D17,Dagslogg[Dato],"<="&D17+6),"")
C18: =C17+1 -> 35 | D18: =D17+7 -> 46258 | E18: =IF(COUNTIFS(Dagslogg[Dato],D18,Dagslogg[Minus],"<>")=0,"",SUMIFS(Dagslogg[Minus],Dagslogg[Dato],D18)) | F18: =D18+1 -> 46259 | G18: =IF(COUNTIFS(Dagslogg[Dato],F18,Dagslogg[Minus],"<>")=0,"",SUMIFS(Dagslogg[Minus],Dagslogg[Dato],F18)) | H18: =F18+1 -> 46260 | I18: =IF(COUNTIFS(Dagslogg[Dato],H18,Dagslogg[Minus],"<>")=0,"",SUMIFS(Dagslogg[Minus],Dagslogg[Dato],H18)) | J18: =H18+1 -> 46261 | K18: =IF(COUNTIFS(Dagslogg[Dato],J18,Dagslogg[Minus],"<>")=0,"",SUMIFS(Dagslogg[Minus],Dagslogg[Dato],J18)) | L18: =J18+1 -> 46262 | M18: =IF(COUNTIFS(Dagslogg[Dato],L18,Dagslogg[Minus],"<>")=0,"",SUMIFS(Dagslogg[Minus],Dagslogg[Dato],L18)) | N18: =L18+1 -> 46263 | O18: =IF(COUNTIFS(Dagslogg[Dato],N18,Dagslogg[Minus],"<>")=0,"",SUMIFS(Dagslogg[Minus],Dagslogg[Dato],N18)) | P18: =N18+1 -> 46264 | Q18: =IF(COUNTIFS(Dagslogg[Dato],P18,Dagslogg[Minus],"<>")=0,"",SUMIFS(Dagslogg[Minus],Dagslogg[Dato],P18)) | R18: =IF(COUNT(E18,G18,I18,K18,M18,O18,Q18)=0,"",SUM(E18,G18,I18,K18,M18,O18,Q18)) | S18: =IF(R18="","",T18*COUNT(E18,G18,I18,K18,M18,O18,Q18)) | T18: 1000 | U18: =IF(R18="","",R18/$E$7) | V18: =IF(R18="","",$E$5-SUM($U$14:U18)) | W18: =IFERROR(AVERAGEIFS(Dagslogg[Vekt],Dagslogg[Dato],">="&D18,Dagslogg[Dato],"<="&D18+6),"") | X18: =IF(OR(W18="",V18=""),"",W18-V18) | Y18: =IFERROR(AVERAGEIFS(Dagslogg[Vidde],Dagslogg[Dato],">="&D18,Dagslogg[Dato],"<="&D18+6),"")
B19: SEPTEMBER | C19: =C18+1 -> 36 | D19: =D18+7 -> 46265 | E19: =IF(COUNTIFS(Dagslogg[Dato],D19,Dagslogg[Minus],"<>")=0,"",SUMIFS(Dagslogg[Minus],Dagslogg[Dato],D19)) | F19: =D19+1 -> 46266 | G19: =IF(COUNTIFS(Dagslogg[Dato],F19,Dagslogg[Minus],"<>")=0,"",SUMIFS(Dagslogg[Minus],Dagslogg[Dato],F19)) | H19: =F19+1 -> 46267 | I19: =IF(COUNTIFS(Dagslogg[Dato],H19,Dagslogg[Minus],"<>")=0,"",SUMIFS(Dagslogg[Minus],Dagslogg[Dato],H19)) | J19: =H19+1 -> 46268 | K19: =IF(COUNTIFS(Dagslogg[Dato],J19,Dagslogg[Minus],"<>")=0,"",SUMIFS(Dagslogg[Minus],Dagslogg[Dato],J19)) | L19: =J19+1 -> 46269 | M19: =IF(COUNTIFS(Dagslogg[Dato],L19,Dagslogg[Minus],"<>")=0,"",SUMIFS(Dagslogg[Minus],Dagslogg[Dato],L19)) | N19: =L19+1 -> 46270 | O19: =IF(COUNTIFS(Dagslogg[Dato],N19,Dagslogg[Minus],"<>")=0,"",SUMIFS(Dagslogg[Minus],Dagslogg[Dato],N19)) | P19: =N19+1 -> 46271 | Q19: =IF(COUNTIFS(Dagslogg[Dato],P19,Dagslogg[Minus],"<>")=0,"",SUMIFS(Dagslogg[Minus],Dagslogg[Dato],P19)) | R19: =IF(COUNT(E19,G19,I19,K19,M19,O19,Q19)=0,"",SUM(E19,G19,I19,K19,M19,O19,Q19)) | S19: =IF(R19="","",T19*COUNT(E19,G19,I19,K19,M19,O19,Q19)) | T19: 900 | U19: =IF(R19="","",R19/$E$7) | V19: =IF(R19="","",$E$5-SUM($U$14:U19)) | W19: =IFERROR(AVERAGEIFS(Dagslogg[Vekt],Dagslogg[Dato],">="&D19,Dagslogg[Dato],"<="&D19+6),"") | X19: =IF(OR(W19="",V19=""),"",W19-V19) | Y19: =IFERROR(AVERAGEIFS(Dagslogg[Vidde],Dagslogg[Dato],">="&D19,Dagslogg[Dato],"<="&D19+6),"")
C20: =C19+1 -> 37 | D20: =D19+7 -> 46272 | E20: =IF(COUNTIFS(Dagslogg[Dato],D20,Dagslogg[Minus],"<>")=0,"",SUMIFS(Dagslogg[Minus],Dagslogg[Dato],D20)) | F20: =D20+1 -> 46273 | G20: =IF(COUNTIFS(Dagslogg[Dato],F20,Dagslogg[Minus],"<>")=0,"",SUMIFS(Dagslogg[Minus],Dagslogg[Dato],F20)) | H20: =F20+1 -> 46274 | I20: =IF(COUNTIFS(Dagslogg[Dato],H20,Dagslogg[Minus],"<>")=0,"",SUMIFS(Dagslogg[Minus],Dagslogg[Dato],H20)) | J20: =H20+1 -> 46275 | K20: =IF(COUNTIFS(Dagslogg[Dato],J20,Dagslogg[Minus],"<>")=0,"",SUMIFS(Dagslogg[Minus],Dagslogg[Dato],J20)) | L20: =J20+1 -> 46276 | M20: =IF(COUNTIFS(Dagslogg[Dato],L20,Dagslogg[Minus],"<>")=0,"",SUMIFS(Dagslogg[Minus],Dagslogg[Dato],L20)) | N20: =L20+1 -> 46277 | O20: =IF(COUNTIFS(Dagslogg[Dato],N20,Dagslogg[Minus],"<>")=0,"",SUMIFS(Dagslogg[Minus],Dagslogg[Dato],N20)) | P20: =N20+1 -> 46278 | Q20: =IF(COUNTIFS(Dagslogg[Dato],P20,Dagslogg[Minus],"<>")=0,"",SUMIFS(Dagslogg[Minus],Dagslogg[Dato],P20)) | R20: =IF(COUNT(E20,G20,I20,K20,M20,O20,Q20)=0,"",SUM(E20,G20,I20,K20,M20,O20,Q20)) | S20: =IF(R20="","",T20*COUNT(E20,G20,I20,K20,M20,O20,Q20)) | T20: 900 | U20: =IF(R20="","",R20/$E$7) | V20: =IF(R20="","",$E$5-SUM($U$14:U20)) | W20: =IFERROR(AVERAGEIFS(Dagslogg[Vekt],Dagslogg[Dato],">="&D20,Dagslogg[Dato],"<="&D20+6),"") | X20: =IF(OR(W20="",V20=""),"",W20-V20) | Y20: =IFERROR(AVERAGEIFS(Dagslogg[Vidde],Dagslogg[Dato],">="&D20,Dagslogg[Dato],"<="&D20+6),"")
C21: =C20+1 -> 38 | D21: =D20+7 -> 46279 | E21: =IF(COUNTIFS(Dagslogg[Dato],D21,Dagslogg[Minus],"<>")=0,"",SUMIFS(Dagslogg[Minus],Dagslogg[Dato],D21)) | F21: =D21+1 -> 46280 | G21: =IF(COUNTIFS(Dagslogg[Dato],F21,Dagslogg[Minus],"<>")=0,"",SUMIFS(Dagslogg[Minus],Dagslogg[Dato],F21)) | H21: =F21+1 -> 46281 | I21: =IF(COUNTIFS(Dagslogg[Dato],H21,Dagslogg[Minus],"<>")=0,"",SUMIFS(Dagslogg[Minus],Dagslogg[Dato],H21)) | J21: =H21+1 -> 46282 | K21: =IF(COUNTIFS(Dagslogg[Dato],J21,Dagslogg[Minus],"<>")=0,"",SUMIFS(Dagslogg[Minus],Dagslogg[Dato],J21)) | L21: =J21+1 -> 46283 | M21: =IF(COUNTIFS(Dagslogg[Dato],L21,Dagslogg[Minus],"<>")=0,"",SUMIFS(Dagslogg[Minus],Dagslogg[Dato],L21)) | N21: =L21+1 -> 46284 | O21: =IF(COUNTIFS(Dagslogg[Dato],N21,Dagslogg[Minus],"<>")=0,"",SUMIFS(Dagslogg[Minus],Dagslogg[Dato],N21)) | P21: =N21+1 -> 46285 | Q21: =IF(COUNTIFS(Dagslogg[Dato],P21,Dagslogg[Minus],"<>")=0,"",SUMIFS(Dagslogg[Minus],Dagslogg[Dato],P21)) | R21: =IF(COUNT(E21,G21,I21,K21,M21,O21,Q21)=0,"",SUM(E21,G21,I21,K21,M21,O21,Q21)) | S21: =IF(R21="","",T21*COUNT(E21,G21,I21,K21,M21,O21,Q21)) | T21: 900 | U21: =IF(R21="","",R21/$E$7) | V21: =IF(R21="","",$E$5-SUM($U$14:U21)) | W21: =IFERROR(AVERAGEIFS(Dagslogg[Vekt],Dagslogg[Dato],">="&D21,Dagslogg[Dato],"<="&D21+6),"") | X21: =IF(OR(W21="",V21=""),"",W21-V21) | Y21: =IFERROR(AVERAGEIFS(Dagslogg[Vidde],Dagslogg[Dato],">="&D21,Dagslogg[Dato],"<="&D21+6),"")
C22: =C21+1 -> 39 | D22: =D21+7 -> 46286 | E22: =IF(COUNTIFS(Dagslogg[Dato],D22,Dagslogg[Minus],"<>")=0,"",SUMIFS(Dagslogg[Minus],Dagslogg[Dato],D22)) | F22: =D22+1 -> 46287 | G22: =IF(COUNTIFS(Dagslogg[Dato],F22,Dagslogg[Minus],"<>")=0,"",SUMIFS(Dagslogg[Minus],Dagslogg[Dato],F22)) | H22: =F22+1 -> 46288 | I22: =IF(COUNTIFS(Dagslogg[Dato],H22,Dagslogg[Minus],"<>")=0,"",SUMIFS(Dagslogg[Minus],Dagslogg[Dato],H22)) | J22: =H22+1 -> 46289 | K22: =IF(COUNTIFS(Dagslogg[Dato],J22,Dagslogg[Minus],"<>")=0,"",SUMIFS(Dagslogg[Minus],Dagslogg[Dato],J22)) | L22: =J22+1 -> 46290 | M22: =IF(COUNTIFS(Dagslogg[Dato],L22,Dagslogg[Minus],"<>")=0,"",SUMIFS(Dagslogg[Minus],Dagslogg[Dato],L22)) | N22: =L22+1 -> 46291 | O22: =IF(COUNTIFS(Dagslogg[Dato],N22,Dagslogg[Minus],"<>")=0,"",SUMIFS(Dagslogg[Minus],Dagslogg[Dato],N22)) | P22: =N22+1 -> 46292 | Q22: =IF(COUNTIFS(Dagslogg[Dato],P22,Dagslogg[Minus],"<>")=0,"",SUMIFS(Dagslogg[Minus],Dagslogg[Dato],P22)) | R22: =IF(COUNT(E22,G22,I22,K22,M22,O22,Q22)=0,"",SUM(E22,G22,I22,K22,M22,O22,Q22)) | S22: =IF(R22="","",T22*COUNT(E22,G22,I22,K22,M22,O22,Q22)) | T22: 900 | U22: =IF(R22="","",R22/$E$7) | V22: =IF(R22="","",$E$5-SUM($U$14:U22)) | W22: =IFERROR(AVERAGEIFS(Dagslogg[Vekt],Dagslogg[Dato],">="&D22,Dagslogg[Dato],"<="&D22+6),"") | X22: =IF(OR(W22="",V22=""),"",W22-V22) | Y22: =IFERROR(AVERAGEIFS(Dagslogg[Vidde],Dagslogg[Dato],">="&D22,Dagslogg[Dato],"<="&D22+6),"")
B23: OKTOBER | C23: =C22+1 -> 40 | D23: =D22+7 -> 46293 | E23: =IF(COUNTIFS(Dagslogg[Dato],D23,Dagslogg[Minus],"<>")=0,"",SUMIFS(Dagslogg[Minus],Dagslogg[Dato],D23)) | F23: =D23+1 -> 46294 | G23: =IF(COUNTIFS(Dagslogg[Dato],F23,Dagslogg[Minus],"<>")=0,"",SUMIFS(Dagslogg[Minus],Dagslogg[Dato],F23)) | H23: =F23+1 -> 46295 | I23: =IF(COUNTIFS(Dagslogg[Dato],H23,Dagslogg[Minus],"<>")=0,"",SUMIFS(Dagslogg[Minus],Dagslogg[Dato],H23)) | J23: =H23+1 -> 46296 | K23: =IF(COUNTIFS(Dagslogg[Dato],J23,Dagslogg[Minus],"<>")=0,"",SUMIFS(Dagslogg[Minus],Dagslogg[Dato],J23)) | L23: =J23+1 -> 46297 | M23: =IF(COUNTIFS(Dagslogg[Dato],L23,Dagslogg[Minus],"<>")=0,"",SUMIFS(Dagslogg[Minus],Dagslogg[Dato],L23)) | N23: =L23+1 -> 46298 | O23: =IF(COUNTIFS(Dagslogg[Dato],N23,Dagslogg[Minus],"<>")=0,"",SUMIFS(Dagslogg[Minus],Dagslogg[Dato],N23)) | P23: =N23+1 -> 46299 | Q23: =IF(COUNTIFS(Dagslogg[Dato],P23,Dagslogg[Minus],"<>")=0,"",SUMIFS(Dagslogg[Minus],Dagslogg[Dato],P23)) | R23: =IF(COUNT(E23,G23,I23,K23,M23,O23,Q23)=0,"",SUM(E23,G23,I23,K23,M23,O23,Q23)) | S23: =IF(R23="","",T23*COUNT(E23,G23,I23,K23,M23,O23,Q23)) | T23: 800 | U23: =IF(R23="","",R23/$E$7) | V23: =IF(R23="","",$E$5-SUM($U$14:U23)) | W23: =IFERROR(AVERAGEIFS(Dagslogg[Vekt],Dagslogg[Dato],">="&D23,Dagslogg[Dato],"<="&D23+6),"") | X23: =IF(OR(W23="",V23=""),"",W23-V23) | Y23: =IFERROR(AVERAGEIFS(Dagslogg[Vidde],Dagslogg[Dato],">="&D23,Dagslogg[Dato],"<="&D23+6),"")
C24: =C23+1 -> 41 | D24: =D23+7 -> 46300 | E24: =IF(COUNTIFS(Dagslogg[Dato],D24,Dagslogg[Minus],"<>")=0,"",SUMIFS(Dagslogg[Minus],Dagslogg[Dato],D24)) | F24: =D24+1 -> 46301 | G24: =IF(COUNTIFS(Dagslogg[Dato],F24,Dagslogg[Minus],"<>")=0,"",SUMIFS(Dagslogg[Minus],Dagslogg[Dato],F24)) | H24: =F24+1 -> 46302 | I24: =IF(COUNTIFS(Dagslogg[Dato],H24,Dagslogg[Minus],"<>")=0,"",SUMIFS(Dagslogg[Minus],Dagslogg[Dato],H24)) | J24: =H24+1 -> 46303 | K24: =IF(COUNTIFS(Dagslogg[Dato],J24,Dagslogg[Minus],"<>")=0,"",SUMIFS(Dagslogg[Minus],Dagslogg[Dato],J24)) | L24: =J24+1 -> 46304 | M24: =IF(COUNTIFS(Dagslogg[Dato],L24,Dagslogg[Minus],"<>")=0,"",SUMIFS(Dagslogg[Minus],Dagslogg[Dato],L24)) | N24: =L24+1 -> 46305 | O24: =IF(COUNTIFS(Dagslogg[Dato],N24,Dagslogg[Minus],"<>")=0,"",SUMIFS(Dagslogg[Minus],Dagslogg[Dato],N24)) | P24: =N24+1 -> 46306 | Q24: =IF(COUNTIFS(Dagslogg[Dato],P24,Dagslogg[Minus],"<>")=0,"",SUMIFS(Dagslogg[Minus],Dagslogg[Dato],P24)) | R24: =IF(COUNT(E24,G24,I24,K24,M24,O24,Q24)=0,"",SUM(E24,G24,I24,K24,M24,O24,Q24)) | S24: =IF(R24="","",T24*COUNT(E24,G24,I24,K24,M24,O24,Q24)) | T24: 800 | U24: =IF(R24="","",R24/$E$7) | V24: =IF(R24="","",$E$5-SUM($U$14:U24)) | W24: =IFERROR(AVERAGEIFS(Dagslogg[Vekt],Dagslogg[Dato],">="&D24,Dagslogg[Dato],"<="&D24+6),"") | X24: =IF(OR(W24="",V24=""),"",W24-V24) | Y24: =IFERROR(AVERAGEIFS(Dagslogg[Vidde],Dagslogg[Dato],">="&D24,Dagslogg[Dato],"<="&D24+6),"")
C25: =C24+1 -> 42 | D25: =D24+7 -> 46307 | E25: =IF(COUNTIFS(Dagslogg[Dato],D25,Dagslogg[Minus],"<>")=0,"",SUMIFS(Dagslogg[Minus],Dagslogg[Dato],D25)) | F25: =D25+1 -> 46308 | G25: =IF(COUNTIFS(Dagslogg[Dato],F25,Dagslogg[Minus],"<>")=0,"",SUMIFS(Dagslogg[Minus],Dagslogg[Dato],F25)) | H25: =F25+1 -> 46309 | I25: =IF(COUNTIFS(Dagslogg[Dato],H25,Dagslogg[Minus],"<>")=0,"",SUMIFS(Dagslogg[Minus],Dagslogg[Dato],H25)) | J25: =H25+1 -> 46310 | K25: =IF(COUNTIFS(Dagslogg[Dato],J25,Dagslogg[Minus],"<>")=0,"",SUMIFS(Dagslogg[Minus],Dagslogg[Dato],J25)) | L25: =J25+1 -> 46311 | M25: =IF(COUNTIFS(Dagslogg[Dato],L25,Dagslogg[Minus],"<>")=0,"",SUMIFS(Dagslogg[Minus],Dagslogg[Dato],L25)) | N25: =L25+1 -> 46312 | O25: =IF(COUNTIFS(Dagslogg[Dato],N25,Dagslogg[Minus],"<>")=0,"",SUMIFS(Dagslogg[Minus],Dagslogg[Dato],N25)) | P25: =N25+1 -> 46313 | Q25: =IF(COUNTIFS(Dagslogg[Dato],P25,Dagslogg[Minus],"<>")=0,"",SUMIFS(Dagslogg[Minus],Dagslogg[Dato],P25)) | R25: =IF(COUNT(E25,G25,I25,K25,M25,O25,Q25)=0,"",SUM(E25,G25,I25,K25,M25,O25,Q25)) | S25: =IF(R25="","",T25*COUNT(E25,G25,I25,K25,M25,O25,Q25)) | T25: 800 | U25: =IF(R25="","",R25/$E$7) | V25: =IF(R25="","",$E$5-SUM($U$14:U25)) | W25: =IFERROR(AVERAGEIFS(Dagslogg[Vekt],Dagslogg[Dato],">="&D25,Dagslogg[Dato],"<="&D25+6),"") | X25: =IF(OR(W25="",V25=""),"",W25-V25) | Y25: =IFERROR(AVERAGEIFS(Dagslogg[Vidde],Dagslogg[Dato],">="&D25,Dagslogg[Dato],"<="&D25+6),"") | Z25: GRAFDATA (automatisk – ikke rediger)
C26: =C25+1 -> 43 | D26: =D25+7 -> 46314 | E26: =IF(COUNTIFS(Dagslogg[Dato],D26,Dagslogg[Minus],"<>")=0,"",SUMIFS(Dagslogg[Minus],Dagslogg[Dato],D26)) | F26: =D26+1 -> 46315 | G26: =IF(COUNTIFS(Dagslogg[Dato],F26,Dagslogg[Minus],"<>")=0,"",SUMIFS(Dagslogg[Minus],Dagslogg[Dato],F26)) | H26: =F26+1 -> 46316 | I26: =IF(COUNTIFS(Dagslogg[Dato],H26,Dagslogg[Minus],"<>")=0,"",SUMIFS(Dagslogg[Minus],Dagslogg[Dato],H26)) | J26: =H26+1 -> 46317 | K26: =IF(COUNTIFS(Dagslogg[Dato],J26,Dagslogg[Minus],"<>")=0,"",SUMIFS(Dagslogg[Minus],Dagslogg[Dato],J26)) | L26: =J26+1 -> 46318 | M26: =IF(COUNTIFS(Dagslogg[Dato],L26,Dagslogg[Minus],"<>")=0,"",SUMIFS(Dagslogg[Minus],Dagslogg[Dato],L26)) | N26: =L26+1 -> 46319 | O26: =IF(COUNTIFS(Dagslogg[Dato],N26,Dagslogg[Minus],"<>")=0,"",SUMIFS(Dagslogg[Minus],Dagslogg[Dato],N26)) | P26: =N26+1 -> 46320 | Q26: =IF(COUNTIFS(Dagslogg[Dato],P26,Dagslogg[Minus],"<>")=0,"",SUMIFS(Dagslogg[Minus],Dagslogg[Dato],P26)) | R26: =IF(COUNT(E26,G26,I26,K26,M26,O26,Q26)=0,"",SUM(E26,G26,I26,K26,M26,O26,Q26)) | S26: =IF(R26="","",T26*COUNT(E26,G26,I26,K26,M26,O26,Q26)) | T26: 800 | U26: =IF(R26="","",R26/$E$7) | V26: =IF(R26="","",$E$5-SUM($U$14:U26)) | W26: =IFERROR(AVERAGEIFS(Dagslogg[Vekt],Dagslogg[Dato],">="&D26,Dagslogg[Dato],"<="&D26+6),"") | X26: =IF(OR(W26="",V26=""),"",W26-V26) | Y26: =IFERROR(AVERAGEIFS(Dagslogg[Vidde],Dagslogg[Dato],">="&D26,Dagslogg[Dato],"<="&D26+6),"") | Z26: UKE | AA26: EST. VEKT | AB26: SNITTVEKT
C27: =C26+1 -> 44 | D27: =D26+7 -> 46321 | E27: =IF(COUNTIFS(Dagslogg[Dato],D27,Dagslogg[Minus],"<>")=0,"",SUMIFS(Dagslogg[Minus],Dagslogg[Dato],D27)) | F27: =D27+1 -> 46322 | G27: =IF(COUNTIFS(Dagslogg[Dato],F27,Dagslogg[Minus],"<>")=0,"",SUMIFS(Dagslogg[Minus],Dagslogg[Dato],F27)) | H27: =F27+1 -> 46323 | I27: =IF(COUNTIFS(Dagslogg[Dato],H27,Dagslogg[Minus],"<>")=0,"",SUMIFS(Dagslogg[Minus],Dagslogg[Dato],H27)) | J27: =H27+1 -> 46324 | K27: =IF(COUNTIFS(Dagslogg[Dato],J27,Dagslogg[Minus],"<>")=0,"",SUMIFS(Dagslogg[Minus],Dagslogg[Dato],J27)) | L27: =J27+1 -> 46325 | M27: =IF(COUNTIFS(Dagslogg[Dato],L27,Dagslogg[Minus],"<>")=0,"",SUMIFS(Dagslogg[Minus],Dagslogg[Dato],L27)) | N27: =L27+1 -> 46326 | O27: =IF(COUNTIFS(Dagslogg[Dato],N27,Dagslogg[Minus],"<>")=0,"",SUMIFS(Dagslogg[Minus],Dagslogg[Dato],N27)) | P27: =N27+1 -> 46327 | Q27: =IF(COUNTIFS(Dagslogg[Dato],P27,Dagslogg[Minus],"<>")=0,"",SUMIFS(Dagslogg[Minus],Dagslogg[Dato],P27)) | R27: =IF(COUNT(E27,G27,I27,K27,M27,O27,Q27)=0,"",SUM(E27,G27,I27,K27,M27,O27,Q27)) | S27: =IF(R27="","",T27*COUNT(E27,G27,I27,K27,M27,O27,Q27)) | T27: 700 | U27: =IF(R27="","",R27/$E$7) | V27: =IF(R27="","",$E$5-SUM($U$14:U27)) | W27: =IFERROR(AVERAGEIFS(Dagslogg[Vekt],Dagslogg[Dato],">="&D27,Dagslogg[Dato],"<="&D27+6),"") | X27: =IF(OR(W27="",V27=""),"",W27-V27) | Y27: =IFERROR(AVERAGEIFS(Dagslogg[Vidde],Dagslogg[Dato],">="&D27,Dagslogg[Dato],"<="&D27+6),"") | Z27: =C14 -> 31 | AA27: =IF(R14="",NA(),V14) -> 77.17 | AB27: =IF(W14="",NA(),W14) -> 77.5
B28: NOVEMBER | C28: =C27+1 -> 45 | D28: =D27+7 -> 46328 | E28: =IF(COUNTIFS(Dagslogg[Dato],D28,Dagslogg[Minus],"<>")=0,"",SUMIFS(Dagslogg[Minus],Dagslogg[Dato],D28)) | F28: =D28+1 -> 46329 | G28: =IF(COUNTIFS(Dagslogg[Dato],F28,Dagslogg[Minus],"<>")=0,"",SUMIFS(Dagslogg[Minus],Dagslogg[Dato],F28)) | H28: =F28+1 -> 46330 | I28: =IF(COUNTIFS(Dagslogg[Dato],H28,Dagslogg[Minus],"<>")=0,"",SUMIFS(Dagslogg[Minus],Dagslogg[Dato],H28)) | J28: =H28+1 -> 46331 | K28: =IF(COUNTIFS(Dagslogg[Dato],J28,Dagslogg[Minus],"<>")=0,"",SUMIFS(Dagslogg[Minus],Dagslogg[Dato],J28)) | L28: =J28+1 -> 46332 | M28: =IF(COUNTIFS(Dagslogg[Dato],L28,Dagslogg[Minus],"<>")=0,"",SUMIFS(Dagslogg[Minus],Dagslogg[Dato],L28)) | N28: =L28+1 -> 46333 | O28: =IF(COUNTIFS(Dagslogg[Dato],N28,Dagslogg[Minus],"<>")=0,"",SUMIFS(Dagslogg[Minus],Dagslogg[Dato],N28)) | P28: =N28+1 -> 46334 | Q28: =IF(COUNTIFS(Dagslogg[Dato],P28,Dagslogg[Minus],"<>")=0,"",SUMIFS(Dagslogg[Minus],Dagslogg[Dato],P28)) | R28: =IF(COUNT(E28,G28,I28,K28,M28,O28,Q28)=0,"",SUM(E28,G28,I28,K28,M28,O28,Q28)) | S28: =IF(R28="","",T28*COUNT(E28,G28,I28,K28,M28,O28,Q28)) | T28: 700 | U28: =IF(R28="","",R28/$E$7) | V28: =IF(R28="","",$E$5-SUM($U$14:U28)) | W28: =IFERROR(AVERAGEIFS(Dagslogg[Vekt],Dagslogg[Dato],">="&D28,Dagslogg[Dato],"<="&D28+6),"") | X28: =IF(OR(W28="",V28=""),"",W28-V28) | Y28: =IFERROR(AVERAGEIFS(Dagslogg[Vidde],Dagslogg[Dato],">="&D28,Dagslogg[Dato],"<="&D28+6),"") | Z28: =C15 -> 32 | AA28: =IF(R15="",NA(),V15) -> #N/A | AB28: =IF(W15="",NA(),W15) -> #N/A
C29: =C28+1 -> 46 | D29: =D28+7 -> 46335 | E29: =IF(COUNTIFS(Dagslogg[Dato],D29,Dagslogg[Minus],"<>")=0,"",SUMIFS(Dagslogg[Minus],Dagslogg[Dato],D29)) | F29: =D29+1 -> 46336 | G29: =IF(COUNTIFS(Dagslogg[Dato],F29,Dagslogg[Minus],"<>")=0,"",SUMIFS(Dagslogg[Minus],Dagslogg[Dato],F29)) | H29: =F29+1 -> 46337 | I29: =IF(COUNTIFS(Dagslogg[Dato],H29,Dagslogg[Minus],"<>")=0,"",SUMIFS(Dagslogg[Minus],Dagslogg[Dato],H29)) | J29: =H29+1 -> 46338 | K29: =IF(COUNTIFS(Dagslogg[Dato],J29,Dagslogg[Minus],"<>")=0,"",SUMIFS(Dagslogg[Minus],Dagslogg[Dato],J29)) | L29: =J29+1 -> 46339 | M29: =IF(COUNTIFS(Dagslogg[Dato],L29,Dagslogg[Minus],"<>")=0,"",SUMIFS(Dagslogg[Minus],Dagslogg[Dato],L29)) | N29: =L29+1 -> 46340 | O29: =IF(COUNTIFS(Dagslogg[Dato],N29,Dagslogg[Minus],"<>")=0,"",SUMIFS(Dagslogg[Minus],Dagslogg[Dato],N29)) | P29: =N29+1 -> 46341 | Q29: =IF(COUNTIFS(Dagslogg[Dato],P29,Dagslogg[Minus],"<>")=0,"",SUMIFS(Dagslogg[Minus],Dagslogg[Dato],P29)) | R29: =IF(COUNT(E29,G29,I29,K29,M29,O29,Q29)=0,"",SUM(E29,G29,I29,K29,M29,O29,Q29)) | S29: =IF(R29="","",T29*COUNT(E29,G29,I29,K29,M29,O29,Q29)) | T29: 700 | U29: =IF(R29="","",R29/$E$7) | V29: =IF(R29="","",$E$5-SUM($U$14:U29)) | W29: =IFERROR(AVERAGEIFS(Dagslogg[Vekt],Dagslogg[Dato],">="&D29,Dagslogg[Dato],"<="&D29+6),"") | X29: =IF(OR(W29="",V29=""),"",W29-V29) | Y29: =IFERROR(AVERAGEIFS(Dagslogg[Vidde],Dagslogg[Dato],">="&D29,Dagslogg[Dato],"<="&D29+6),"") | Z29: =C16 -> 33 | AA29: =IF(R16="",NA(),V16) -> #N/A | AB29: =IF(W16="",NA(),W16) -> #N/A
C30: =C29+1 -> 47 | D30: =D29+7 -> 46342 | E30: =IF(COUNTIFS(Dagslogg[Dato],D30,Dagslogg[Minus],"<>")=0,"",SUMIFS(Dagslogg[Minus],Dagslogg[Dato],D30)) | F30: =D30+1 -> 46343 | G30: =IF(COUNTIFS(Dagslogg[Dato],F30,Dagslogg[Minus],"<>")=0,"",SUMIFS(Dagslogg[Minus],Dagslogg[Dato],F30)) | H30: =F30+1 -> 46344 | I30: =IF(COUNTIFS(Dagslogg[Dato],H30,Dagslogg[Minus],"<>")=0,"",SUMIFS(Dagslogg[Minus],Dagslogg[Dato],H30)) | J30: =H30+1 -> 46345 | K30: =IF(COUNTIFS(Dagslogg[Dato],J30,Dagslogg[Minus],"<>")=0,"",SUMIFS(Dagslogg[Minus],Dagslogg[Dato],J30)) | L30: =J30+1 -> 46346 | M30: =IF(COUNTIFS(Dagslogg[Dato],L30,Dagslogg[Minus],"<>")=0,"",SUMIFS(Dagslogg[Minus],Dagslogg[Dato],L30)) | N30: =L30+1 -> 46347 | O30: =IF(COUNTIFS(Dagslogg[Dato],N30,Dagslogg[Minus],"<>")=0,"",SUMIFS(Dagslogg[Minus],Dagslogg[Dato],N30)) | P30: =N30+1 -> 46348 | Q30: =IF(COUNTIFS(Dagslogg[Dato],P30,Dagslogg[Minus],"<>")=0,"",SUMIFS(Dagslogg[Minus],Dagslogg[Dato],P30)) | R30: =IF(COUNT(E30,G30,I30,K30,M30,O30,Q30)=0,"",SUM(E30,G30,I30,K30,M30,O30,Q30)) | S30: =IF(R30="","",T30*COUNT(E30,G30,I30,K30,M30,O30,Q30)) | T30: 700 | U30: =IF(R30="","",R30/$E$7) | V30: =IF(R30="","",$E$5-SUM($U$14:U30)) | W30: =IFERROR(AVERAGEIFS(Dagslogg[Vekt],Dagslogg[Dato],">="&D30,Dagslogg[Dato],"<="&D30+6),"") | X30: =IF(OR(W30="",V30=""),"",W30-V30) | Y30: =IFERROR(AVERAGEIFS(Dagslogg[Vidde],Dagslogg[Dato],">="&D30,Dagslogg[Dato],"<="&D30+6),"") | Z30: =C17 -> 34 | AA30: =IF(R17="",NA(),V17) -> #N/A | AB30: =IF(W17="",NA(),W17) -> #N/A
C31: =C30+1 -> 48 | D31: =D30+7 -> 46349 | E31: =IF(COUNTIFS(Dagslogg[Dato],D31,Dagslogg[Minus],"<>")=0,"",SUMIFS(Dagslogg[Minus],Dagslogg[Dato],D31)) | F31: =D31+1 -> 46350 | G31: =IF(COUNTIFS(Dagslogg[Dato],F31,Dagslogg[Minus],"<>")=0,"",SUMIFS(Dagslogg[Minus],Dagslogg[Dato],F31)) | H31: =F31+1 -> 46351 | I31: =IF(COUNTIFS(Dagslogg[Dato],H31,Dagslogg[Minus],"<>")=0,"",SUMIFS(Dagslogg[Minus],Dagslogg[Dato],H31)) | J31: =H31+1 -> 46352 | K31: =IF(COUNTIFS(Dagslogg[Dato],J31,Dagslogg[Minus],"<>")=0,"",SUMIFS(Dagslogg[Minus],Dagslogg[Dato],J31)) | L31: =J31+1 -> 46353 | M31: =IF(COUNTIFS(Dagslogg[Dato],L31,Dagslogg[Minus],"<>")=0,"",SUMIFS(Dagslogg[Minus],Dagslogg[Dato],L31)) | N31: =L31+1 -> 46354 | O31: =IF(COUNTIFS(Dagslogg[Dato],N31,Dagslogg[Minus],"<>")=0,"",SUMIFS(Dagslogg[Minus],Dagslogg[Dato],N31)) | P31: =N31+1 -> 46355 | Q31: =IF(COUNTIFS(Dagslogg[Dato],P31,Dagslogg[Minus],"<>")=0,"",SUMIFS(Dagslogg[Minus],Dagslogg[Dato],P31)) | R31: =IF(COUNT(E31,G31,I31,K31,M31,O31,Q31)=0,"",SUM(E31,G31,I31,K31,M31,O31,Q31)) | S31: =IF(R31="","",T31*COUNT(E31,G31,I31,K31,M31,O31,Q31)) | T31: 600 | U31: =IF(R31="","",R31/$E$7) | V31: =IF(R31="","",$E$5-SUM($U$14:U31)) | W31: =IFERROR(AVERAGEIFS(Dagslogg[Vekt],Dagslogg[Dato],">="&D31,Dagslogg[Dato],"<="&D31+6),"") | X31: =IF(OR(W31="",V31=""),"",W31-V31) | Y31: =IFERROR(AVERAGEIFS(Dagslogg[Vidde],Dagslogg[Dato],">="&D31,Dagslogg[Dato],"<="&D31+6),"") | Z31: =C18 -> 35 | AA31: =IF(R18="",NA(),V18) -> #N/A | AB31: =IF(W18="",NA(),W18) -> #N/A
B32: DESEMBER | C32: =C31+1 -> 49 | D32: =D31+7 -> 46356 | E32: =IF(COUNTIFS(Dagslogg[Dato],D32,Dagslogg[Minus],"<>")=0,"",SUMIFS(Dagslogg[Minus],Dagslogg[Dato],D32)) | F32: =D32+1 -> 46357 | G32: =IF(COUNTIFS(Dagslogg[Dato],F32,Dagslogg[Minus],"<>")=0,"",SUMIFS(Dagslogg[Minus],Dagslogg[Dato],F32)) | H32: =F32+1 -> 46358 | I32: =IF(COUNTIFS(Dagslogg[Dato],H32,Dagslogg[Minus],"<>")=0,"",SUMIFS(Dagslogg[Minus],Dagslogg[Dato],H32)) | J32: =H32+1 -> 46359 | K32: =IF(COUNTIFS(Dagslogg[Dato],J32,Dagslogg[Minus],"<>")=0,"",SUMIFS(Dagslogg[Minus],Dagslogg[Dato],J32)) | L32: =J32+1 -> 46360 | M32: =IF(COUNTIFS(Dagslogg[Dato],L32,Dagslogg[Minus],"<>")=0,"",SUMIFS(Dagslogg[Minus],Dagslogg[Dato],L32)) | N32: =L32+1 -> 46361 | O32: =IF(COUNTIFS(Dagslogg[Dato],N32,Dagslogg[Minus],"<>")=0,"",SUMIFS(Dagslogg[Minus],Dagslogg[Dato],N32)) | P32: =N32+1 -> 46362 | Q32: =IF(COUNTIFS(Dagslogg[Dato],P32,Dagslogg[Minus],"<>")=0,"",SUMIFS(Dagslogg[Minus],Dagslogg[Dato],P32)) | R32: =IF(COUNT(E32,G32,I32,K32,M32,O32,Q32)=0,"",SUM(E32,G32,I32,K32,M32,O32,Q32)) | S32: =IF(R32="","",T32*COUNT(E32,G32,I32,K32,M32,O32,Q32)) | T32: 600 | U32: =IF(R32="","",R32/$E$7) | V32: =IF(R32="","",$E$5-SUM($U$14:U32)) | W32: =IFERROR(AVERAGEIFS(Dagslogg[Vekt],Dagslogg[Dato],">="&D32,Dagslogg[Dato],"<="&D32+6),"") | X32: =IF(OR(W32="",V32=""),"",W32-V32) | Y32: =IFERROR(AVERAGEIFS(Dagslogg[Vidde],Dagslogg[Dato],">="&D32,Dagslogg[Dato],"<="&D32+6),"") | Z32: =C19 -> 36 | AA32: =IF(R19="",NA(),V19) -> #N/A | AB32: =IF(W19="",NA(),W19) -> #N/A
C33: =C32+1 -> 50 | D33: =D32+7 -> 46363 | E33: =IF(COUNTIFS(Dagslogg[Dato],D33,Dagslogg[Minus],"<>")=0,"",SUMIFS(Dagslogg[Minus],Dagslogg[Dato],D33)) | F33: =D33+1 -> 46364 | G33: =IF(COUNTIFS(Dagslogg[Dato],F33,Dagslogg[Minus],"<>")=0,"",SUMIFS(Dagslogg[Minus],Dagslogg[Dato],F33)) | H33: =F33+1 -> 46365 | I33: =IF(COUNTIFS(Dagslogg[Dato],H33,Dagslogg[Minus],"<>")=0,"",SUMIFS(Dagslogg[Minus],Dagslogg[Dato],H33)) | J33: =H33+1 -> 46366 | K33: =IF(COUNTIFS(Dagslogg[Dato],J33,Dagslogg[Minus],"<>")=0,"",SUMIFS(Dagslogg[Minus],Dagslogg[Dato],J33)) | L33: =J33+1 -> 46367 | M33: =IF(COUNTIFS(Dagslogg[Dato],L33,Dagslogg[Minus],"<>")=0,"",SUMIFS(Dagslogg[Minus],Dagslogg[Dato],L33)) | N33: =L33+1 -> 46368 | O33: =IF(COUNTIFS(Dagslogg[Dato],N33,Dagslogg[Minus],"<>")=0,"",SUMIFS(Dagslogg[Minus],Dagslogg[Dato],N33)) | P33: =N33+1 -> 46369 | Q33: =IF(COUNTIFS(Dagslogg[Dato],P33,Dagslogg[Minus],"<>")=0,"",SUMIFS(Dagslogg[Minus],Dagslogg[Dato],P33)) | R33: =IF(COUNT(E33,G33,I33,K33,M33,O33,Q33)=0,"",SUM(E33,G33,I33,K33,M33,O33,Q33)) | S33: =IF(R33="","",T33*COUNT(E33,G33,I33,K33,M33,O33,Q33)) | T33: 600 | U33: =IF(R33="","",R33/$E$7) | V33: =IF(R33="","",$E$5-SUM($U$14:U33)) | W33: =IFERROR(AVERAGEIFS(Dagslogg[Vekt],Dagslogg[Dato],">="&D33,Dagslogg[Dato],"<="&D33+6),"") | X33: =IF(OR(W33="",V33=""),"",W33-V33) | Y33: =IFERROR(AVERAGEIFS(Dagslogg[Vidde],Dagslogg[Dato],">="&D33,Dagslogg[Dato],"<="&D33+6),"") | Z33: =C20 -> 37 | AA33: =IF(R20="",NA(),V20) -> #N/A | AB33: =IF(W20="",NA(),W20) -> #N/A
C34: =C33+1 -> 51 | D34: =D33+7 -> 46370 | E34: =IF(COUNTIFS(Dagslogg[Dato],D34,Dagslogg[Minus],"<>")=0,"",SUMIFS(Dagslogg[Minus],Dagslogg[Dato],D34)) | F34: =D34+1 -> 46371 | G34: =IF(COUNTIFS(Dagslogg[Dato],F34,Dagslogg[Minus],"<>")=0,"",SUMIFS(Dagslogg[Minus],Dagslogg[Dato],F34)) | H34: =F34+1 -> 46372 | I34: =IF(COUNTIFS(Dagslogg[Dato],H34,Dagslogg[Minus],"<>")=0,"",SUMIFS(Dagslogg[Minus],Dagslogg[Dato],H34)) | J34: =H34+1 -> 46373 | K34: =IF(COUNTIFS(Dagslogg[Dato],J34,Dagslogg[Minus],"<>")=0,"",SUMIFS(Dagslogg[Minus],Dagslogg[Dato],J34)) | L34: =J34+1 -> 46374 | M34: =IF(COUNTIFS(Dagslogg[Dato],L34,Dagslogg[Minus],"<>")=0,"",SUMIFS(Dagslogg[Minus],Dagslogg[Dato],L34)) | N34: =L34+1 -> 46375 | O34: =IF(COUNTIFS(Dagslogg[Dato],N34,Dagslogg[Minus],"<>")=0,"",SUMIFS(Dagslogg[Minus],Dagslogg[Dato],N34)) | P34: =N34+1 -> 46376 | Q34: =IF(COUNTIFS(Dagslogg[Dato],P34,Dagslogg[Minus],"<>")=0,"",SUMIFS(Dagslogg[Minus],Dagslogg[Dato],P34)) | R34: =IF(COUNT(E34,G34,I34,K34,M34,O34,Q34)=0,"",SUM(E34,G34,I34,K34,M34,O34,Q34)) | S34: =IF(R34="","",T34*COUNT(E34,G34,I34,K34,M34,O34,Q34)) | T34: 600 | U34: =IF(R34="","",R34/$E$7) | V34: =IF(R34="","",$E$5-SUM($U$14:U34)) | W34: =IFERROR(AVERAGEIFS(Dagslogg[Vekt],Dagslogg[Dato],">="&D34,Dagslogg[Dato],"<="&D34+6),"") | X34: =IF(OR(W34="",V34=""),"",W34-V34) | Y34: =IFERROR(AVERAGEIFS(Dagslogg[Vidde],Dagslogg[Dato],">="&D34,Dagslogg[Dato],"<="&D34+6),"") | Z34: =C21 -> 38 | AA34: =IF(R21="",NA(),V21) -> #N/A | AB34: =IF(W21="",NA(),W21) -> #N/A
B35: TOTALT | R35: =SUM(R14:R34) -> 2100 | S35: =SUM(S14:S34) -> 2000 | U35: =SUM(U14:U34) -> 0.28 | Z35: =C22 -> 39 | AA35: =IF(R22="",NA(),V22) -> #N/A | AB35: =IF(W22="",NA(),W22) -> #N/A
Z36: =C23 -> 40 | AA36: =IF(R23="",NA(),V23) -> #N/A | AB36: =IF(W23="",NA(),W23) -> #N/A
Z37: =C24 -> 41 | AA37: =IF(R24="",NA(),V24) -> #N/A | AB37: =IF(W24="",NA(),W24) -> #N/A
Z38: =C25 -> 42 | AA38: =IF(R25="",NA(),V25) -> #N/A | AB38: =IF(W25="",NA(),W25) -> #N/A
Z39: =C26 -> 43 | AA39: =IF(R26="",NA(),V26) -> #N/A | AB39: =IF(W26="",NA(),W26) -> #N/A
Z40: =C27 -> 44 | AA40: =IF(R27="",NA(),V27) -> #N/A | AB40: =IF(W27="",NA(),W27) -> #N/A
Z41: =C28 -> 45 | AA41: =IF(R28="",NA(),V28) -> #N/A | AB41: =IF(W28="",NA(),W28) -> #N/A
...

Sheet Dagslogg
B1: DAGSLOGG — HØST 2026
B2: Én rad per dag. Fyll inn kaloriunderskudd, vekt og livvidde — Vekt-arket henter alt herfra.
A3: Dato | B3: Uke | C3: Ukedag | D3: Minus | E3: Vekt | F3: Vidde | G3: Kommentar
A4: =Vekt!$E$4+ROW()-4 -> 46230 | B4: =_xlfn.ISOWEEKNUM(Dagslogg[[#This Row],[Dato]]) -> 31 | C4: =TEXT(Dagslogg[[#This Row],[Dato]],"ddd") -> man
A5: =Vekt!$E$4+ROW()-4 -> 46231 | B5: =_xlfn.ISOWEEKNUM(Dagslogg[[#This Row],[Dato]]) -> 31 | C5: =TEXT(Dagslogg[[#This Row],[Dato]],"ddd") -> tir | D5: 1000 | E5: 77.5 | F5: 89
A6: =Vekt!$E$4+ROW()-4 -> 46232 | B6: =_xlfn.ISOWEEKNUM(Dagslogg[[#This Row],[Dato]]) -> 31 | C6: =TEXT(Dagslogg[[#This Row],[Dato]],"ddd") -> ons | D6: 1100 | E6: 77.5 | F6: 88.5
A7: =Vekt!$E$4+ROW()-4 -> 46233 | B7: =_xlfn.ISOWEEKNUM(Dagslogg[[#This Row],[Dato]]) -> 31 | C7: =TEXT(Dagslogg[[#This Row],[Dato]],"ddd") -> tor
A8: =Vekt!$E$4+ROW()-4 -> 46234 | B8: =_xlfn.ISOWEEKNUM(Dagslogg[[#This Row],[Dato]]) -> 31 | C8: =TEXT(Dagslogg[[#This Row],[Dato]],"ddd") -> fre
A9: =Vekt!$E$4+ROW()-4 -> 46235 | B9: =_xlfn.ISOWEEKNUM(Dagslogg[[#This Row],[Dato]]) -> 31 | C9: =TEXT(Dagslogg[[#This Row],[Dato]],"ddd") -> lør
A10: =Vekt!$E$4+ROW()-4 -> 46236 | B10: =_xlfn.ISOWEEKNUM(Dagslogg[[#This Row],[Dato]]) -> 31 | C10: =TEXT(Dagslogg[[#This Row],[Dato]],"ddd") -> søn
A11: =Vekt!$E$4+ROW()-4 -> 46237 | B11: =_xlfn.ISOWEEKNUM(Dagslogg[[#This Row],[Dato]]) -> 32 | C11: =TEXT(Dagslogg[[#This Row],[Dato]],"ddd") -> man
